Workbook

Sheet Summary
A1: £000's | C1: FY24 | D1: FY25 | E1: FY26 | F1: FY27 | G1: FY28
A3: Screens
A4: ISP Owned | C4: ='KPI''s'!U7 -> 300 | D4: ='KPI''s'!AG7 -> 630 | E4: ='KPI''s'!AS7 -> 1062 | F4: ='KPI''s'!BE7 -> 1578 | G4: ='KPI''s'!BQ7 -> 2202
A5: In-home Media Owned | C5: ='KPI''s'!U8 -> 62 | D5: ='KPI''s'!AG8 -> 532 | E5: ='KPI''s'!AS8 -> 1108 | F5: ='KPI''s'!BE8 -> 1780 | G5: ='KPI''s'!BQ8 -> 2548
A6: Total | C6: =SUM(C4:C5) -> 362 | D6: =SUM(D4:D5) -> 1162 | E6: =SUM(E4:E5) -> 2170 | F6: =SUM(F4:F5) -> 3358 | G6: =SUM(G4:G5) -> 4750
A8: One off Revenue | C8: ='Financials Annual'!J7 -> 477408 | D8: ='Financials Annual'!K7 -> 806250 | E8: ='Financials Annual'!L7 -> 1152360 | F8: ='Financials Annual'!M7 -> 1509717 | G8: ='Financials Annual'!N7 -> 1813548
A9: Recurring Revenue | C9: ='Financials Annual'!J8 -> 225650 | D9: ='Financials Annual'!K8 -> 1927125 | E9: ='Financials Annual'!L8 -> 5115792 | F9: ='Financials Annual'!M8 -> 9517878.2 | G9: ='Financials Annual'!N8 -> 14098993
A10: Total Revenue | C10: =SUM(C8:C9) -> 703058 | D10: =SUM(D8:D9) -> 2733375 | E10: =SUM(E8:E9) -> 6268152 | F10: =SUM(F8:F9) -> 11027595 | G10: =SUM(G8:G9) -> 15912541
A12: Gross Profit | C12: ='Financials Annual'!J19 -> 296569 | D12: ='Financials Annual'!K19 -> 1055673 | E12: ='Financials Annual'!L19 -> 3423842.7 | F12: ='Financials Annual'!M19 -> 6828602.2 | G12: ='Financials Annual'!N19 -> 10155861
A13: Gross Margin | C13: ='Financials Annual'!J20 -> 0.42182722 | D13: ='Financials Annual'!K20 -> 0.38621594 | E13: ='Financials Annual'!L20 -> 0.5462284 | F13: ='Financials Annual'!M20 -> 0.61922859 | G13: ='Financials Annual'!N20 -> 0.63822999
A15: Administrative expenses | C15: ='Financials Annual'!J28 -> 453909.25 | D15: ='Financials Annual'!K28 -> 854359.5 | E15: ='Financials Annual'!L28 -> 964229.5 | F15: ='Financials Annual'!M28 -> 1077323.3 | G15: ='Financials Annual'!N28 -> 1213119.8
A17: EBITDA | C17: ='Financials Annual'!J30 -> -157340.25 | D17: ='Financials Annual'!K30 -> 201313.5 | E17: ='Financials Annual'!L30 -> 2459613.2 | F17: ='Financials Annual'!M30 -> 5751278.9 | G17: ='Financials Annual'!N30 -> 8942740.9
A18: EBITDA % | C18: ='Financials Annual'!J31 -> -0.22379413 | D18: ='Financials Annual'!K31 -> 0.073650158 | E18: ='Financials Annual'!L31 -> 0.39239846 | F18: ='Financials Annual'!M31 -> 0.52153519 | G18: ='Financials Annual'!N31 -> 0.56199328
A20: Cashflow | C20: ='Financials Annual'!J148 -> -250520.8 | D20: ='Financials Annual'!K148 -> -400123.85 | E20: ='Financials Annual'!L148 -> 1765344.1 | F20: ='Financials Annual'!M148 -> 4279997.6 | G20: ='Financials Annual'!N148 -> 6628536.2
A21: Closing Cash | C21: ='Financials Annual'!J150 -> -250520.8 | D21: ='Financials Annual'!K150 -> -650644.65 | E21: ='Financials Annual'!L150 -> 1114699.5 | F21: ='Financials Annual'!M150 -> 5394697.1 | G21: ='Financials Annual'!N150 -> 12023233
A23: Cash lowpoint | C23: =MIN('Financials Monthly'!J150:BQ150) -> -722826.32 | D23: ='Financials Monthly'!AD3 -> 45626
A24: Cash flow breakeven | D24: ='Financials Monthly'!AN3 -> 45930

Sheet KPI's
A1: Business 1
A2: KPI's | J2: =Timing!J2 -> 44986 | K2: =Timing!K2 -> 45017 | L2: =Timing!L2 -> 45047 | M2: =Timing!M2 -> 45078 | N2: =Timing!N2 -> 45108 | O2: =Timing!O2 -> 45139 | P2: =Timing!P2 -> 45170 | Q2: =Timing!Q2 -> 45200 | ... BQ2: =Timing!BQ2 -> 46784
J3: =Timing!J3 -> 45016 | K3: =Timing!K3 -> 45046 | L3: =Timing!L3 -> 45077 | M3: =Timing!M3 -> 45107 | N3: =Timing!N3 -> 45138 | O3: =Timing!O3 -> 45169 | P3: =Timing!P3 -> 45199 | Q3: =Timing!Q3 -> 45230 | ... BQ3: =Timing!BQ3 -> 46812
B6: Total Screens
B7: ISP Owned | J7: =Inputs!J33 -> 90 | K7: =Inputs!K33 -> 120 | L7: =Inputs!L33 -> 120 | M7: =Inputs!M33 -> 150 | N7: =Inputs!N33 -> 180 | O7: =Inputs!O33 -> 240 | P7: =Inputs!P33 -> 300 | Q7: =Inputs!Q33 -> 300 | ... BQ7: =Inputs!BQ33 -> 2202
B8: In-home Media Owned | J8: =Inputs!J37+Inputs!J41+Inputs!J45 -> 0 | K8: =Inputs!K37+Inputs!K41+Inputs!K45 -> 0 | L8: =Inputs!L37+Inputs!L41+Inputs!L45 -> 0 | M8: =Inputs!M37+Inputs!M41+Inputs!M45 -> 0 | N8: =Inputs!N37+Inputs!N41+Inputs!N45 -> 0 | O8: =Inputs!O37+Inputs!O41+Inputs!O45 -> 0 | P8: =Inputs!P37+Inputs!P41+Inputs!P45 -> 0 | Q8: =Inputs!Q37+Inputs!Q41+Inputs!Q45 -> 0 | ... BQ8: =Inputs!BQ37+Inputs!BQ41+Inputs!BQ45 -> 2548
B9: Total | J9: =SUM(J7:J8) -> 90 | K9: =SUM(K7:K8) -> 120 | L9: =SUM(L7:L8) -> 120 | M9: =SUM(M7:M8) -> 150 | N9: =SUM(N7:N8) -> 180 | O9: =SUM(O7:O8) -> 240 | P9: =SUM(P7:P8) -> 300 | Q9: =SUM(Q7:Q8) -> 300 | ... BQ9: =SUM(BQ7:BQ8) -> 4750
B12: Screens Added by Month
B13: ISP Owned | J13: =Inputs!J32 -> 30 | K13: =Inputs!K32 -> 30 | L13: =Inputs!L32 -> 0 | M13: =Inputs!M32 -> 30 | N13: =Inputs!N32 -> 30 | O13: =Inputs!O32 -> 30 | P13: =Inputs!P32 -> 60 | Q13: =Inputs!Q32 -> 0 | ... BQ13: =Inputs!BQ32 -> 52
B14: In-home Media Owned | J14: =Inputs!J36+Inputs!J40+Inputs!J44 -> 0 | K14: =Inputs!K36+Inputs!K40+Inputs!K44 -> 0 | L14: =Inputs!L36+Inputs!L40+Inputs!L44 -> 0 | M14: =Inputs!M36+Inputs!M40+Inputs!M44 -> 0 | N14: =Inputs!N36+Inputs!N40+Inputs!N44 -> 0 | O14: =Inputs!O36+Inputs!O40+Inputs!O44 -> 0 | P14: =Inputs!P36+Inputs!P40+Inputs!P44 -> 0 | Q14: =Inputs!Q36+Inputs!Q40+Inputs!Q44 -> 0 | ... BQ14: =Inputs!BQ36+Inputs!BQ40+Inputs!BQ44 -> 64
B15: Total | J15: =SUM(J13:J14) -> 30 | K15: =SUM(K13:K14) -> 30 | L15: =SUM(L13:L14) -> 0 | M15: =SUM(M13:M14) -> 30 | N15: =SUM(N13:N14) -> 30 | O15: =SUM(O13:O14) -> 30 | P15: =SUM(P13:P14) -> 60 | Q15: =SUM(Q13:Q14) -> 0 | ... BQ15: =SUM(BQ13:BQ14) -> 116

Sheet Financials Annual
A1: Business 1 | B1: Business 1
A2: Financials | B2: Financials -Annual
J3: FY24 | K3: FY25 | L3: FY26 | M3: FY27 | N3: FY28
B4: PROFIT & LOSS | J4: 45323 | K4: 45689 | L4: 46054 | M4: 46419 | N4: 46784
B6: Revenue
C7: One off Revenue | J7: =SUM('Financials Monthly'!J7:U7) -> 477408 | K7: =SUM('Financials Monthly'!V7:AG7) -> 806250 | L7: =SUM('Financials Monthly'!AH7:AS7) -> 1152360 | M7: =SUM('Financials Monthly'!AT7:BE7) -> 1509717 | N7: =SUM('Financials Monthly'!BF7:BQ7) -> 1813548
C8: Recurring Revenue | J8: =SUM('Financials Monthly'!J8:U8) -> 225650 | K8: =SUM('Financials Monthly'!V8:AG8) -> 1927125 | L8: =SUM('Financials Monthly'!AH8:AS8) -> 5115792 | M8: =SUM('Financials Monthly'!AT8:BE8) -> 9517878.2 | N8: =SUM('Financials Monthly'!BF8:BQ8) -> 14098993
C9: Other Revenue | J9: =SUM('Financials Monthly'!J9:U9) -> 0 | K9: =SUM('Financials Monthly'!V9:AG9) -> 0 | L9: =SUM('Financials Monthly'!AH9:AS9) -> 0 | M9: =SUM('Financials Monthly'!AT9:BE9) -> 0 | N9: =SUM('Financials Monthly'!AU9:BF9) -> 0
C10: Total | J10: =SUM('Financials Monthly'!J10:U10) -> 703058 | K10: =SUM('Financials Monthly'!V10:AG10) -> 2733375 | L10: =SUM('Financials Monthly'!AH10:AS10) -> 6268152 | M10: =SUM('Financials Monthly'!AT10:BE10) -> 11027595 | N10: =SUM('Financials Monthly'!BF10:BQ10) -> 15912541
B12: Cost of sales
C13: Cost of Sales | J13: =SUM('Financials Monthly'!J13:U13) -> 381414 | K13: =SUM('Financials Monthly'!V13:AG13) -> 1385652 | L13: =SUM('Financials Monthly'!AH13:AS13) -> 2486376 | M13: =SUM('Financials Monthly'!AT13:BE13) -> 3744693 | N13: =SUM('Financials Monthly'!BF13:BQ13) -> 5249280
C14: Gross Wages and Salaries (COS) | J14: =SUM('Financials Monthly'!J14:U14) -> 21250 | K14: =SUM('Financials Monthly'!V14:AG14) -> 247500 | L14: =SUM('Financials Monthly'!AH14:AS14) -> 303333.33 | M14: =SUM('Financials Monthly'!AT14:BE14) -> 385000 | N14: =SUM('Financials Monthly'!BF14:BQ14) -> 430000
C15: COS Ers NI | J15: =SUM('Financials Monthly'!J15:U15) -> 3187.5 | K15: =SUM('Financials Monthly'!V15:AG15) -> 37125 | L15: =SUM('Financials Monthly'!AH15:AS15) -> 45500 | M15: =SUM('Financials Monthly'!AT15:BE15) -> 57750 | N15: =SUM('Financials Monthly'!BF15:BQ15) -> 64500
C16: COS Ers Pension | J16: =SUM('Financials Monthly'!J16:U16) -> 637.5 | K16: =SUM('Financials Monthly'!V16:AG16) -> 7425 | L16: =SUM('Financials Monthly'!AH16:AS16) -> 9100 | M16: =SUM('Financials Monthly'!AT16:BE16) -> 11550 | N16: =SUM('Financials Monthly'!BF16:BQ16) -> 12900
C17: Total | J17: =SUM('Financials Monthly'!J17:U17) -> 406489 | K17: =SUM('Financials Monthly'!V17:AG17) -> 1677702 | L17: =SUM('Financials Monthly'!AH17:AS17) -> 2844309.3 | M17: =SUM('Financials Monthly'!AT17:BE17) -> 4198993 | N17: =SUM('Financials Monthly'!BF17:BQ17) -> 5756680
B19: Gross profit | J19: =J10-J17 -> 296569 | K19: =K10-K17 -> 1055673 | L19: =L10-L17 -> 3423842.7 | M19: =M10-M17 -> 6828602.2 | N19: =N10-N17 -> 10155861
C20: GP margin (%) | J20: =J19/J10 -> 0.42182722 | K20: =K19/K10 -> 0.38621594 | L20: =L19/L10 -> 0.5462284 | M20: =M19/M10 -> 0.61922859 | N20: =N19/N10 -> 0.63822999
B22: Administrative expenses
C23: Gross wages and Salaries (Admin Expenses) | J23: =SUM('Financials Monthly'!J23:U23) -> 37500 | K23: =SUM('Financials Monthly'!V23:AG23) -> 91250 | L23: =SUM('Financials Monthly'!AH23:AS23) -> 125000 | M23: =SUM('Financials Monthly'!AT23:BE23) -> 160000 | N23: =SUM('Financials Monthly'!BF23:BQ23) -> 195000
C24: Wages and Salaries Er's NI | J24: =SUM('Financials Monthly'!J24:U24) -> 1875 | K24: =SUM('Financials Monthly'!V24:AG24) -> 13687.5 | L24: =SUM('Financials Monthly'!AH24:AS24) -> 18750 | M24: =SUM('Financials Monthly'!AT24:BE24) -> 24000 | N24: =SUM('Financials Monthly'!BF24:BQ24) -> 29250
C25: Wages and Salaries Pension | J25: =SUM('Financials Monthly'!J25:U25) -> 375 | K25: =SUM('Financials Monthly'!V25:AG25) -> 2737.5 | L25: =SUM('Financials Monthly'!AH25:AS25) -> 3750 | M25: =SUM('Financials Monthly'!AT25:BE25) -> 4800 | N25: =SUM('Financials Monthly'!BF25:BQ25) -> 5850
C26: Directors wages and Salaries (Incl Ni and Pension) | J26: =SUM('Financials Monthly'!J26:U26) -> 0 | K26: =SUM('Financials Monthly'!V26:AG26) -> 453375 | L26: =SUM('Financials Monthly'!AH26:AS26) -> 526500 | M26: =SUM('Financials Monthly'!AT26:BE26) -> 526500 | N26: =SUM('Financials Monthly'!BF26:BQ26) -> 526500
C27: Other Administrative Expenses | J27: =SUM('Financials Monthly'!J27:U27) -> 414159.25 | K27: =SUM('Financials Monthly'!V27:AG27) -> 293309.5 | L27: =SUM('Financials Monthly'!AH27:AS27) -> 290229.5 | M27: =SUM('Financials Monthly'!AT27:BE27) -> 362023.25 | N27: =SUM('Financials Monthly'!BF27:BQ27) -> 456519.75
C28: Total | J28: =SUM('Financials Monthly'!J28:U28) -> 453909.25 | K28: =SUM('Financials Monthly'!V28:AG28) -> 854359.5 | L28: =SUM('Financials Monthly'!AH28:AS28) -> 964229.5 | M28: =SUM('Financials Monthly'!AT28:BE28) -> 1077323.3 | N28: =SUM('Financials Monthly'!BF28:BQ28) -> 1213119.8
C30: EBITDA | J30: =SUM('Financials Monthly'!J30:U30) -> -157340.25 | K30: =SUM('Financials Monthly'!V30:AG30) -> 201313.5 | L30: =SUM('Financials Monthly'!AH30:AS30) -> 2459613.2 | M30: =SUM('Financials Monthly'!AT30:BE30) -> 5751278.9 | N30: =SUM('Financials Monthly'!BF30:BQ30) -> 8942740.9
C31: EBITDA (%) | J31: =J30/J10 -> -0.22379413 | K31: =K30/K10 -> 0.073650158 | L31: =L30/L10 -> 0.39239846 | M31: =M30/M10 -> 0.52153519 | N31: =N30/N10 -> 0.56199328
B33: Non-Operational Costs
C34: Exceptional Costs | J34: =SUM('Financials Monthly'!J34:U34) -> 0 | K34: =SUM('Financials Monthly'!V34:AG34) -> 0 | L34: =SUM('Financials Monthly'!AH34:AS34) -> 0 | M34: =SUM('Financials Monthly'!AT34:BE34) -> 0 | N34: =SUM('Financials Monthly'!AU34:BF34) -> 0
C35: Investor Fees | J35: =SUM('Financials Monthly'!J35:U35) -> 0 | K35: =SUM('Financials Monthly'!V35:AG35) -> 0 | L35: =SUM('Financials Monthly'!AH35:AS35) -> 0 | M35: =SUM('Financials Monthly'!AT35:BE35) -> 0 | N35: =SUM('Financials Monthly'!AU35:BF35) -> 0
C36: Adjusted EBITDA | J36: =SUM('Financials Monthly'!J36:U36) -> -157340.25 | K36: =SUM('Financials Monthly'!V36:AG36) -> 201313.5 | L36: =SUM('Financials Monthly'!AH36:AS36) -> 2459613.2 | M36: =SUM('Financials Monthly'!AT36:BE36) -> 5751278.9 | N36: =SUM('Financials Monthly'!BF36:BQ36) -> 8942740.9
B38: Depreciation and amortisation
C39: Depreciation | J39: =SUM('Financials Monthly'!J39:U39) -> 1077.9167 | K39: =SUM('Financials Monthly'!V39:AG39) -> 46117.5 | L39: =SUM('Financials Monthly'!AH39:AS39) -> 130975 | M39: =SUM('Financials Monthly'!AT39:BE39) -> 229287.5 | N39: =SUM('Financials Monthly'!BF39:BQ39) -> 341055
C40: Total | J40: =SUM('Financials Monthly'!J40:U40) -> 1077.9167 | K40: =SUM('Financials Monthly'!V40:AG40) -> 46117.5 | L40: =SUM('Financials Monthly'!AH40:AS40) -> 130975 | M40: =SUM('Financials Monthly'!AT40:BE40) -> 229287.5 | N40: =SUM('Financials Monthly'!BF40:BQ40) -> 341055
C42: EBIT | J42: =SUM('Financials Monthly'!J42:U42) -> -158418.17 | K42: =SUM('Financials Monthly'!V42:AG42) -> 155196 | L42: =SUM('Financials Monthly'!AH42:AS42) -> 2328638.2 | M42: =SUM('Financials Monthly'!AT42:BE42) -> 5521991.4 | N42: =SUM('Financials Monthly'!BF42:BQ42) -> 8601685.9
C43: EBIT (%) | J43: =J42/J10 -> -0.22532731 | K43: =K42/K10 -> 0.056778159 | L43: =L42/L10 -> 0.37150314 | M43: =M42/M10 -> 0.50074303 | N43: =N42/N10 -> 0.54056018
B45: Interest chargeable and receivable
C47: Interest | J47: =SUM('Financials Monthly'!J47:U47) -> 0 | K47: =SUM('Financials Monthly'!V47:AG47) -> 0 | L47: =SUM('Financials Monthly'!AH47:AS47) -> 0 | M47: =SUM('Financials Monthly'!AT47:BE47) -> 0 | N47: =SUM('Financials Monthly'!AU47:BF47) -> 0
C48: Total | J48: =SUM('Financials Monthly'!J48:U48) -> -158418.17 | K48: =SUM('Financials Monthly'!V48:AG48) -> 155196 | L48: =SUM('Financials Monthly'!AH48:AS48) -> 2328638.2 | M48: =SUM('Financials Monthly'!AT48:BE48) -> 5521991.4 | N48: =SUM('Financials Monthly'!BF48:BQ48) -> 8601685.9
C50: Profit before Tax | J50: =SUM('Financials Monthly'!J50:U50) -> -158418.17 | K50: =SUM('Financials Monthly'!V50:AG50) -> 155196 | L50: =SUM('Financials Monthly'!AH50:AS50) -> 2328638.2 | M50: =SUM('Financials Monthly'!AT50:BE50) -> 5521991.4 | N50: =SUM('Financials Monthly'!BF50:BQ50) -> 8601685.9
C52: Deferred Tax | J52: =SUM('Financials Monthly'!J52:U52) -> 0 | K52: =SUM('Financials Monthly'!V52:AG52) -> 0 | L52: =SUM('Financials Monthly'!AH52:AS52) -> 0 | M52: =SUM('Financials Monthly'!AT52:BE52) -> 0 | N52: =SUM('Financials Monthly'!AU52:BF52) -> 0
...

Sheet Financials Monthly
A1: Business 1 | J1: Act | K1: Act | L1: Act | M1: Act | N1: Act | O1: Act | P1: Act | Q1: Act
A2: Financials - Monthly | J2: =Timing!J2 -> 44986 | K2: =Timing!K2 -> 45017 | L2: =Timing!L2 -> 45047 | M2: =Timing!M2 -> 45078 | N2: =Timing!N2 -> 45108 | O2: =Timing!O2 -> 45139 | P2: =Timing!P2 -> 45170 | Q2: =Timing!Q2 -> 45200 | ... BQ2: =Timing!BQ2 -> 46784
J3: =Timing!J3 -> 45016 | K3: =Timing!K3 -> 45046 | L3: =Timing!L3 -> 45077 | M3: =Timing!M3 -> 45107 | N3: =Timing!N3 -> 45138 | O3: =Timing!O3 -> 45169 | P3: =Timing!P3 -> 45199 | Q3: =Timing!Q3 -> 45230 | ... BQ3: =Timing!BQ3 -> 46812
B4: PROFIT & LOSS
B6: Revenue
C7: One off Revenue | J7: =Revenue!J15 -> 36800 | K7: =Revenue!K15 -> 41550 | L7: =Revenue!L15 -> 5620 | M7: =Revenue!M15 -> 49673 | N7: =Revenue!N15 -> 46274 | O7: =Revenue!O15 -> 144234 | P7: =Revenue!P15 -> 107457 | Q7: =Revenue!Q15 -> 17450 | ... BQ7: =Revenue!BQ15 -> 151129
C8: Recurring Revenue | J8: =Revenue!J31 -> 0 | K8: =Revenue!K31 -> 6750 | L8: =Revenue!L31 -> 9000 | M8: =Revenue!M31 -> 12750 | N8: =Revenue!N31 -> 13500 | O8: =Revenue!O31 -> 13500 | P8: =Revenue!P31 -> 16275 | Q8: =Revenue!Q31 -> 17175 | ... BQ8: =Revenue!BQ31 -> 1366543.8
C9: Other Revenue
C10: Total | J10: =SUM(J7:J9) -> 36800 | K10: =SUM(K7:K9) -> 48300 | L10: =SUM(L7:L9) -> 14620 | M10: =SUM(M7:M9) -> 62423 | N10: =SUM(N7:N9) -> 59774 | O10: =SUM(O7:O9) -> 157734 | P10: =SUM(P7:P9) -> 123732 | Q10: =SUM(Q7:Q9) -> 34625 | ... BQ10: =SUM(BQ7:BQ9) -> 1517672.8
B12: Cost of sales
C13: Cost of Sales | J13: ='COS and Overheads'!J25 -> 19425 | K13: ='COS and Overheads'!K25 -> 7364 | L13: ='COS and Overheads'!L25 -> 28805 | M13: ='COS and Overheads'!M25 -> 25039 | N13: ='COS and Overheads'!N25 -> 31307 | O13: ='COS and Overheads'!O25 -> 103407 | P13: ='COS and Overheads'!P25 -> 64290 | Q13: ='COS and Overheads'!Q25 -> 10629 | ... BQ13: ='COS and Overheads'!BQ25 -> 493111
C14: Gross Wages and Salaries (COS) | J14: ='Wages and Salaries'!J21 -> 0 | K14: ='Wages and Salaries'!K21 -> 0 | L14: ='Wages and Salaries'!L21 -> 0 | M14: ='Wages and Salaries'!M21 -> 0 | N14: ='Wages and Salaries'!N21 -> 0 | O14: ='Wages and Salaries'!O21 -> 0 | P14: ='Wages and Salaries'!P21 -> 0 | Q14: ='Wages and Salaries'!Q21 -> 0 | ... BQ14: ='Wages and Salaries'!BQ21 -> 35833.333
C15: COS Ers NI | J15: ='Wages and Salaries'!J24 -> 0 | K15: ='Wages and Salaries'!K24 -> 0 | L15: ='Wages and Salaries'!L24 -> 0 | M15: ='Wages and Salaries'!M24 -> 0 | N15: ='Wages and Salaries'!N24 -> 0 | O15: ='Wages and Salaries'!O24 -> 0 | P15: ='Wages and Salaries'!P24 -> 0 | Q15: ='Wages and Salaries'!Q24 -> 0 | ... BQ15: ='Wages and Salaries'!BQ24 -> 5375
C16: COS Ers Pension | J16: ='Wages and Salaries'!J25 -> 0 | K16: ='Wages and Salaries'!K25 -> 0 | L16: ='Wages and Salaries'!L25 -> 0 | M16: ='Wages and Salaries'!M25 -> 0 | N16: ='Wages and Salaries'!N25 -> 0 | O16: ='Wages and Salaries'!O25 -> 0 | P16: ='Wages and Salaries'!P25 -> 0 | Q16: ='Wages and Salaries'!Q25 -> 0 | ... BQ16: ='Wages and Salaries'!BQ25 -> 1075
C17: Total | J17: =SUM(J13:J16) -> 19425 | K17: =SUM(K13:K16) -> 7364 | L17: =SUM(L13:L16) -> 28805 | M17: =SUM(M13:M16) -> 25039 | N17: =SUM(N13:N16) -> 31307 | O17: =SUM(O13:O16) -> 103407 | P17: =SUM(P13:P16) -> 64290 | Q17: =SUM(Q13:Q16) -> 10629 | ... BQ17: =SUM(BQ13:BQ16) -> 535394.33
B19: Gross profit | J19: =J10-J17 -> 17375 | K19: =K10-K17 -> 40936 | L19: =L10-L17 -> -14185 | M19: =M10-M17 -> 37384 | N19: =N10-N17 -> 28467 | O19: =O10-O17 -> 54327 | P19: =P10-P17 -> 59442 | Q19: =Q10-Q17 -> 23996 | ... BQ19: =BQ10-BQ17 -> 982278.42
C20: GP margin (%) | J20: =J19/J10 -> 0.47214674 | K20: =K19/K10 -> 0.84753623 | L20: =L19/L10 -> -0.97024624 | M20: =M19/M10 -> 0.59888182 | N20: =N19/N10 -> 0.47624385 | O20: =O19/O10 -> 0.34442162 | P20: =P19/P10 -> 0.48040927 | Q20: =Q19/Q10 -> 0.69302527 | ... BQ20: =BQ19/BQ10 -> 0.64722676
B22: Administrative expenses
C23: Gross wages and Salaries (Admin Expenses) | J23: ='Wages and Salaries'!J47 -> 5000 | K23: ='Wages and Salaries'!K47 -> 0 | L23: ='Wages and Salaries'!L47 -> 5000 | M23: ='Wages and Salaries'!M47 -> 5000 | N23: ='Wages and Salaries'!N47 -> 5000 | O23: ='Wages and Salaries'!O47 -> 5000 | P23: ='Wages and Salaries'!P47 -> 0 | Q23: ='Wages and Salaries'!Q47 -> 0 | ... BQ23: ='Wages and Salaries'!BQ47 -> 16250
C24: Wages and Salaries Er's NI | J24: ='Wages and Salaries'!J50 -> 0 | K24: ='Wages and Salaries'!K50 -> 0 | L24: ='Wages and Salaries'!L50 -> 0 | M24: ='Wages and Salaries'!M50 -> 0 | N24: ='Wages and Salaries'!N50 -> 0 | O24: ='Wages and Salaries'!O50 -> 0 | P24: ='Wages and Salaries'!P50 -> 0 | Q24: ='Wages and Salaries'!Q50 -> 0 | ... BQ24: ='Wages and Salaries'!BQ50 -> 2437.5
C25: Wages and Salaries Pension | J25: ='Wages and Salaries'!J51 -> 0 | K25: ='Wages and Salaries'!K51 -> 0 | L25: ='Wages and Salaries'!L51 -> 0 | M25: ='Wages and Salaries'!M51 -> 0 | N25: ='Wages and Salaries'!N51 -> 0 | O25: ='Wages and Salaries'!O51 -> 0 | P25: ='Wages and Salaries'!P51 -> 0 | Q25: ='Wages and Salaries'!Q51 -> 0 | ... BQ25: ='Wages and Salaries'!BQ51 -> 487.5
C26: Directors wages and Salaries (Incl Ni and Pension) | J26: ='Wages and Salaries'!J73+'Wages and Salaries'!J76+'Wages and Salaries'!J77 -> 0 | K26: ='Wages and Salaries'!K73+'Wages and Salaries'!K76+'Wages and Salaries'!K77 -> 0 | L26: ='Wages and Salaries'!L73+'Wages and Salaries'!L76+'Wages and Salaries'!L77 -> 0 | M26: ='Wages and Salaries'!M73+'Wages and Salaries'!M76+'Wages and Salaries'!M77 -> 0 | N26: ='Wages and Salaries'!N73+'Wages and Salaries'!N76+'Wages and Salaries'!N77 -> 0 | O26: ='Wages and Salaries'!O73+'Wages and Salaries'!O76+'Wages and Salaries'!O77 -> 0 | P26: ='Wages and Salaries'!P73+'Wages and Salaries'!P76+'Wages and Salaries'!P77 -> 0 | Q26: ='Wages and Salaries'!Q73+'Wages and Salaries'!Q76+'Wages and Salaries'!Q77 -> 0 | ... BQ26: ='Wages and Salaries'!BQ73+'Wages and Salaries'!BQ76+'Wages and Salaries'!BQ77 -> 43875
C27: Other Administrative Expenses | J27: ='COS and Overheads'!J46 -> 3252 | K27: ='COS and Overheads'!K46 -> 2398 | L27: ='COS and Overheads'!L46 -> 16019 | M27: ='COS and Overheads'!M46 -> 35404 | N27: ='COS and Overheads'!N46 -> 33427 | O27: ='COS and Overheads'!O46 -> 31398 | P27: ='COS and Overheads'!P46 -> 31033 | Q27: ='COS and Overheads'!Q46 -> 66424 | ... BQ27: ='COS and Overheads'!BQ46 -> 38309.25
C28: Total | J28: =SUM(J23:J27) -> 8252 | K28: =SUM(K23:K27) -> 2398 | L28: =SUM(L23:L27) -> 21019 | M28: =SUM(M23:M27) -> 40404 | N28: =SUM(N23:N27) -> 38427 | O28: =SUM(O23:O27) -> 36398 | P28: =SUM(P23:P27) -> 31033 | Q28: =SUM(Q23:Q27) -> 66424 | ... BQ28: =SUM(BQ23:BQ27) -> 101359.25
C30: EBITDA | J30: =J19-J28 -> 9123 | K30: =K19-K28 -> 38538 | L30: =L19-L28 -> -35204 | M30: =M19-M28 -> -3020 | N30: =N19-N28 -> -9960 | O30: =O19-O28 -> 17929 | P30: =P19-P28 -> 28409 | Q30: =Q19-Q28 -> -42428 | ... BQ30: =BQ19-BQ28 -> 880919.17
C31: EBITDA (%) | J31: =J30/J10 -> 0.24790761 | K31: =K30/K10 -> 0.7978882 | L31: =L30/L10 -> -2.4079343 | M31: =M30/M10 -> -0.048379604 | N31: =N30/N10 -> -0.16662763 | O31: =O30/O10 -> 0.11366605 | P31: =P30/P10 -> 0.22960107 | Q31: =Q30/Q10 -> -1.2253574 | ... BQ31: =BQ30/BQ10 -> 0.58044079
B33: Non-Operational Costs
C34: Exceptional Costs | J34: ='COS and Overheads'!J245 -> 0 | K34: ='COS and Overheads'!K245 -> 0 | L34: ='COS and Overheads'!L245 -> 0 | M34: ='COS and Overheads'!M245 -> 0 | N34: ='COS and Overheads'!N245 -> 0 | O34: ='COS and Overheads'!O245 -> 0 | P34: ='COS and Overheads'!P245 -> 0 | Q34: ='COS and Overheads'!Q245 -> 0 | ... BQ34: ='COS and Overheads'!BQ245 -> 0
C35: Investor Fees | J35: ='COS and Overheads'!J252 -> 0 | K35: ='COS and Overheads'!K252 -> 0 | L35: ='COS and Overheads'!L252 -> 0 | M35: ='COS and Overheads'!M252 -> 0 | N35: ='COS and Overheads'!N252 -> 0 | O35: ='COS and Overheads'!O252 -> 0 | P35: ='COS and Overheads'!P252 -> 0 | Q35: ='COS and Overheads'!Q252 -> 0 | ... BQ35: ='COS and Overheads'!BQ252 -> 0
C36: Adjusted EBITDA | J36: =J30-J34-J35 -> 9123 | K36: =K30-K34-K35 -> 38538 | L36: =L30-L34-L35 -> -35204 | M36: =M30-M34-M35 -> -3020 | N36: =N30-N34-N35 -> -9960 | O36: =O30-O34-O35 -> 17929 | P36: =P30-P34-P35 -> 28409 | Q36: =Q30-Q34-Q35 -> -42428 | ... BQ36: =BQ30-BQ34-BQ35 -> 880919.17
B38: Depreciation and amortisation
C39: Depreciation | J39: ='Fixed Assets'!J73 -> 0 | K39: ='Fixed Assets'!K73 -> 0 | L39: ='Fixed Assets'!L73 -> 0 | M39: ='Fixed Assets'!M73 -> 0 | N39: ='Fixed Assets'!N73 -> 0 | O39: ='Fixed Assets'!O73 -> 0 | P39: ='Fixed Assets'!P73 -> 0 | Q39: ='Fixed Assets'!Q73 -> 0 | ... BQ39: ='Fixed Assets'!BQ73 -> 32949.583
C40: Total | J40: =SUM(J39) -> 0 | K40: =SUM(K39) -> 0 | L40: =SUM(L39) -> 0 | M40: =SUM(M39) -> 0 | N40: =SUM(N39) -> 0 | O40: =SUM(O39) -> 0 | P40: =SUM(P39) -> 0 | Q40: =SUM(Q39) -> 0 | ... BQ40: =SUM(BQ39) -> 32949.583
C42: EBIT | J42: =J36-J40 -> 9123 | K42: =K36-K40 -> 38538 | L42: =L36-L40 -> -35204 | M42: =M36-M40 -> -3020 | N42: =N36-N40 -> -9960 | O42: =O36-O40 -> 17929 | P42: =P36-P40 -> 28409 | Q42: =Q36-Q40 -> -42428 | ... BQ42: =BQ36-BQ40 -> 847969.58
C43: EBIT (%)
B45: Interest chargeable and receivable
C47: Interest
C48: Total | J48: =J42-J47 -> 9123 | K48: =K42-K47 -> 38538 | L48: =L42-L47 -> -35204 | M48: =M42-M47 -> -3020 | N48: =N42-N47 -> -9960 | O48: =O42-O47 -> 17929 | P48: =P42-P47 -> 28409 | Q48: =Q42-Q47 -> -42428 | ... BQ48: =BQ42-BQ47 -> 847969.58
C50: Profit before Tax | J50: =J48 -> 9123 | K50: =K48 -> 38538 | L50: =L48 -> -35204 | M50: =M48 -> -3020 | N50: =N48 -> -9960 | O50: =O48 -> 17929 | P50: =P48 -> 28409 | Q50: =Q48 -> -42428 | ... BQ50: =BQ48 -> 847969.58
C52: Deferred Tax
...

Sheet Timing
A1: Business 1
A2: Timing | J2: 44986 | K2: =EDATE(J2,1) -> 45017 | L2: =EDATE(K2,1) -> 45047 | M2: =EDATE(L2,1) -> 45078 | N2: =EDATE(M2,1) -> 45108 | O2: =EDATE(N2,1) -> 45139 | P2: =EDATE(O2,1) -> 45170 | Q2: =EDATE(P2,1) -> 45200 | R2: =EDATE(Q2,1) -> 45231 | ... BQ2: =EDATE(BP2,1) -> 46784
J3: =IF(EOMONTH(J2,0)>[1]Scen!$F$12,0,EOMONTH(J2,0)) -> 45016 | K3: =EDATE(J3,1) -> 45046 | L3: =IF(EOMONTH(L2,0)>[1]Scen!$F$12,0,EOMONTH(L2,0)) -> 45077 | M3: =IF(EOMONTH(M2,0)>[1]Scen!$F$12,0,EOMONTH(M2,0)) -> 45107 | N3: =IF(EOMONTH(N2,0)>[1]Scen!$F$12,0,EOMONTH(N2,0)) -> 45138 | O3: =IF(EOMONTH(O2,0)>[1]Scen!$F$12,0,EOMONTH(O2,0)) -> 45169 | P3: =IF(EOMONTH(P2,0)>[1]Scen!$F$12,0,EOMONTH(P2,0)) -> 45199 | Q3: =IF(EOMONTH(Q2,0)>[1]Scen!$F$12,0,EOMONTH(Q2,0)) -> 45230 | R3: =IF(EOMONTH(R2,0)>[1]Scen!$F$12,0,EOMONTH(R2,0)) -> 45260 | S3: =IF(EOMONTH(S2,0)>[1]Scen!$F$12,0,EOMONTH(S2,0)) -> 45291 | ... BQ3: =IF(EOMONTH(BQ2,0)>[1]Scen!$F$12,0,EOMONTH(BQ2,0)) -> 46812

Sheet Inputs
A1: Business 1
A2: Inputs | J2: =Timing!J2 -> 44986 | K2: =Timing!K2 -> 45017 | L2: =Timing!L2 -> 45047 | M2: =Timing!M2 -> 45078 | N2: =Timing!N2 -> 45108 | O2: =Timing!O2 -> 45139 | P2: =Timing!P2 -> 45170 | Q2: =Timing!Q2 -> 45200 | ... BQ2: =Timing!BQ2 -> 46784
J3: =Timing!J3 -> 45016 | K3: =Timing!K3 -> 45046 | L3: =Timing!L3 -> 45077 | M3: =Timing!M3 -> 45107 | N3: =Timing!N3 -> 45138 | O3: =Timing!O3 -> 45169 | P3: =Timing!P3 -> 45199 | Q3: =Timing!Q3 -> 45230 | ... BQ3: =Timing!BQ3 -> 46812
B7: Output Vat | J7: 0.2 | K7: 0.2 | L7: 0.2 | M7: 0.2 | N7: 0.2 | O7: 0.2 | P7: 0.2 | Q7: 0.2 | R7: 0.2 | S7: 0.2 | T7: 0.2 | U7: 0.2 | V7: 0.2 | W7: 0.2 | X7: 0.2 | Y7: 0.2 | Z7: 0.2 | AA7: 0.2 | AB7: 0.2 | AC7: 0.2 | AD7: 0.2 | AE7: 0.2 | AF7: 0.2 | AG7: 0.2 | AH7: 0.2 | AI7: 0.2 | AJ7: 0.2 | AK7: 0.2 | AL7: 0.2 | AM7: 0.2 | AN7: 0.2 | AO7: 0.2 | AP7: 0.2 | AQ7: 0.2 | AR7: 0.2 | AS7: 0.2 | AT7: 0.2 | AU7: 0.2 | AV7: 0.2 | AW7: 0.2 | AX7: 0.2 | AY7: 0.2 | AZ7: 0.2 | BA7: 0.2 | BB7: 0.2 | BC7: 0.2 | BD7: 0.2 | BE7: 0.2 | BF7: 0.2 | BG7: 0.2 | BH7: 0.2 | BI7: 0.2 | BJ7: 0.2 | BK7: 0.2 | BL7: 0.2 | BM7: 0.2 | BN7: 0.2 | BO7: 0.2 | BP7: 0.2 | BQ7: 0.2
B8: Input Vat | J8: 0.2 | K8: 0.2 | L8: 0.2 | M8: 0.2 | N8: 0.2 | O8: 0.2 | P8: 0.2 | Q8: 0.2 | R8: 0.2 | S8: 0.2 | T8: 0.2 | U8: 0.2 | V8: 0.2 | W8: 0.2 | X8: 0.2 | Y8: 0.2 | Z8: 0.2 | AA8: 0.2 | AB8: 0.2 | AC8: 0.2 | AD8: 0.2 | AE8: 0.2 | AF8: 0.2 | AG8: 0.2 | AH8: 0.2 | AI8: 0.2 | AJ8: 0.2 | AK8: 0.2 | AL8: 0.2 | AM8: 0.2 | AN8: 0.2 | AO8: 0.2 | AP8: 0.2 | AQ8: 0.2 | AR8: 0.2 | AS8: 0.2 | AT8: 0.2 | AU8: 0.2 | AV8: 0.2 | AW8: 0.2 | AX8: 0.2 | AY8: 0.2 | AZ8: 0.2 | BA8: 0.2 | BB8: 0.2 | BC8: 0.2 | BD8: 0.2 | BE8: 0.2 | BF8: 0.2 | BG8: 0.2 | BH8: 0.2 | BI8: 0.2 | BJ8: 0.2 | BK8: 0.2 | BL8: 0.2 | BM8: 0.2 | BN8: 0.2 | BO8: 0.2 | BP8: 0.2 | BQ8: 0.2
B9: Trade Debtor Days | J9: 45 | K9: 45 | L9: 45 | M9: 45 | N9: 45 | O9: 45 | P9: 45 | Q9: 45 | R9: 45 | S9: 45 | T9: 45 | U9: 45 | V9: 45 | W9: 45 | X9: 45 | Y9: 45 | Z9: 45 | AA9: 45 | AB9: 45 | AC9: 45 | AD9: 45 | AE9: 45 | AF9: 45 | AG9: 45 | AH9: 45 | AI9: 45 | AJ9: 45 | AK9: 45 | AL9: 45 | AM9: 45 | AN9: 45 | AO9: 45 | AP9: 45 | AQ9: 45 | AR9: 45 | AS9: 45 | AT9: 45 | AU9: 45 | AV9: 45 | AW9: 45 | AX9: 45 | AY9: 45 | AZ9: 45 | BA9: 45 | BB9: 45 | BC9: 45 | BD9: 45 | BE9: 45 | BF9: 45 | BG9: 45 | BH9: 45 | BI9: 45 | BJ9: 45 | BK9: 45 | BL9: 45 | BM9: 45 | BN9: 45 | BO9: 45 | BP9: 45 | BQ9: 45
B10: Trade Creditor Days | J10: 30 | K10: 30 | L10: 30 | M10: 30 | N10: 30 | O10: 30 | P10: 30 | Q10: 30 | R10: 30 | S10: 30 | T10: 30 | U10: 30 | V10: 30 | W10: 30 | X10: 30 | Y10: 30 | Z10: 30 | AA10: 30 | AB10: 30 | AC10: 30 | AD10: 30 | AE10: 30 | AF10: 30 | AG10: 30 | AH10: 30 | AI10: 30 | AJ10: 30 | AK10: 30 | AL10: 30 | AM10: 30 | AN10: 30 | AO10: 30 | AP10: 30 | AQ10: 30 | AR10: 30 | AS10: 30 | AT10: 30 | AU10: 30 | AV10: 30 | AW10: 30 | AX10: 30 | AY10: 30 | AZ10: 30 | BA10: 30 | BB10: 30 | BC10: 30 | BD10: 30 | BE10: 30 | BF10: 30 | BG10: 30 | BH10: 30 | BI10: 30 | BJ10: 30 | BK10: 30 | BL10: 30 | BM10: 30 | BN10: 30 | BO10: 30 | BP10: 30 | BQ10: 30
B12: Wages and Salaries PAYE | J12: 0.25 | K12: 0.25 | L12: 0.25 | M12: 0.25 | N12: 0.25 | O12: 0.25 | P12: 0.25 | Q12: 0.25 | R12: 0.25 | S12: 0.25 | T12: 0.25 | U12: 0.25 | V12: 0.25 | W12: 0.25 | X12: 0.25 | Y12: 0.25 | Z12: 0.25 | AA12: 0.25 | AB12: 0.25 | AC12: 0.25 | AD12: 0.25 | AE12: 0.25 | AF12: 0.25 | AG12: 0.25 | AH12: 0.25 | AI12: 0.25 | AJ12: 0.25 | AK12: 0.25 | AL12: 0.25 | AM12: 0.25 | AN12: 0.25 | AO12: 0.25 | AP12: 0.25 | AQ12: 0.25 | AR12: 0.25 | AS12: 0.25 | AT12: 0.25 | AU12: 0.25 | AV12: 0.25 | AW12: 0.25 | AX12: 0.25 | AY12: 0.25 | AZ12: 0.25 | BA12: 0.25 | BB12: 0.25 | BC12: 0.25 | BD12: 0.25 | BE12: 0.25 | BF12: 0.25 | BG12: 0.25 | BH12: 0.25 | BI12: 0.25 | BJ12: 0.25 | BK12: 0.25 | BL12: 0.25 | BM12: 0.25 | BN12: 0.25 | BO12: 0.25 | BP12: 0.25 | BQ12: 0.25
B13: Wages and Salaries Ees NIC | J13: 0.11 | K13: 0.11 | L13: 0.11 | M13: 0.11 | N13: 0.11 | O13: 0.11 | P13: 0.11 | Q13: 0.11 | R13: 0.11 | S13: 0.11 | T13: 0.11 | U13: 0.11 | V13: 0.11 | W13: 0.11 | X13: 0.11 | Y13: 0.11 | Z13: 0.11 | AA13: 0.11 | AB13: 0.11 | AC13: 0.11 | AD13: 0.11 | AE13: 0.11 | AF13: 0.11 | AG13: 0.11 | AH13: 0.11 | AI13: 0.11 | AJ13: 0.11 | AK13: 0.11 | AL13: 0.11 | AM13: 0.11 | AN13: 0.11 | AO13: 0.11 | AP13: 0.11 | AQ13: 0.11 | AR13: 0.11 | AS13: 0.11 | AT13: 0.11 | AU13: 0.11 | AV13: 0.11 | AW13: 0.11 | AX13: 0.11 | AY13: 0.11 | AZ13: 0.11 | BA13: 0.11 | BB13: 0.11 | BC13: 0.11 | BD13: 0.11 | BE13: 0.11 | BF13: 0.11 | BG13: 0.11 | BH13: 0.11 | BI13: 0.11 | BJ13: 0.11 | BK13: 0.11 | BL13: 0.11 | BM13: 0.11 | BN13: 0.11 | BO13: 0.11 | BP13: 0.11 | BQ13: 0.11
B14: Wages and Salaries Ers NIC | J14: 0.15 | K14: 0.15 | L14: 0.15 | M14: 0.15 | N14: 0.15 | O14: 0.15 | P14: 0.15 | Q14: 0.15 | R14: 0.15 | S14: 0.15 | T14: 0.15 | U14: 0.15 | V14: 0.15 | W14: 0.15 | X14: 0.15 | Y14: 0.15 | Z14: 0.15 | AA14: 0.15 | AB14: 0.15 | AC14: 0.15 | AD14: 0.15 | AE14: 0.15 | AF14: 0.15 | AG14: 0.15 | AH14: 0.15 | AI14: 0.15 | AJ14: 0.15 | AK14: 0.15 | AL14: 0.15 | AM14: 0.15 | AN14: 0.15 | AO14: 0.15 | AP14: 0.15 | AQ14: 0.15 | AR14: 0.15 | AS14: 0.15 | AT14: 0.15 | AU14: 0.15 | AV14: 0.15 | AW14: 0.15 | AX14: 0.15 | AY14: 0.15 | AZ14: 0.15 | BA14: 0.15 | BB14: 0.15 | BC14: 0.15 | BD14: 0.15 | BE14: 0.15 | BF14: 0.15 | BG14: 0.15 | BH14: 0.15 | BI14: 0.15 | BJ14: 0.15 | BK14: 0.15 | BL14: 0.15 | BM14: 0.15 | BN14: 0.15 | BO14: 0.15 | BP14: 0.15 | BQ14: 0.15
B15: Pension Contribution | J15: 0.03 | K15: 0.03 | L15: 0.03 | M15: 0.03 | N15: 0.03 | O15: 0.03 | P15: 0.03 | Q15: 0.03 | R15: 0.03 | S15: 0.03 | T15: 0.03 | U15: 0.03 | V15: 0.03 | W15: 0.03 | X15: 0.03 | Y15: 0.03 | Z15: 0.03 | AA15: 0.03 | AB15: 0.03 | AC15: 0.03 | AD15: 0.03 | AE15: 0.03 | AF15: 0.03 | AG15: 0.03 | AH15: 0.03 | AI15: 0.03 | AJ15: 0.03 | AK15: 0.03 | AL15: 0.03 | AM15: 0.03 | AN15: 0.03 | AO15: 0.03 | AP15: 0.03 | AQ15: 0.03 | AR15: 0.03 | AS15: 0.03 | AT15: 0.03 | AU15: 0.03 | AV15: 0.03 | AW15: 0.03 | AX15: 0.03 | AY15: 0.03 | AZ15: 0.03 | BA15: 0.03 | BB15: 0.03 | BC15: 0.03 | BD15: 0.03 | BE15: 0.03 | BF15: 0.03 | BG15: 0.03 | BH15: 0.03 | BI15: 0.03 | BJ15: 0.03 | BK15: 0.03 | BL15: 0.03 | BM15: 0.03 | BN15: 0.03 | BO15: 0.03 | BP15: 0.03 | BQ15: 0.03
B17: Directors PAYE | J17: 0.35 | K17: 0.35 | L17: 0.35 | M17: 0.35 | N17: 0.35 | O17: 0.35 | P17: 0.35 | Q17: 0.35 | R17: 0.35 | S17: 0.35 | T17: 0.35 | U17: 0.35 | V17: 0.35 | W17: 0.35 | X17: 0.35 | Y17: 0.35 | Z17: 0.35 | AA17: 0.35 | AB17: 0.35 | AC17: 0.35 | AD17: 0.35 | AE17: 0.35 | AF17: 0.35 | AG17: 0.35 | AH17: 0.35 | AI17: 0.35 | AJ17: 0.35 | AK17: 0.35 | AL17: 0.35 | AM17: 0.35 | AN17: 0.35 | AO17: 0.35 | AP17: 0.35 | AQ17: 0.35 | AR17: 0.35 | AS17: 0.35 | AT17: 0.35 | AU17: 0.35 | AV17: 0.35 | AW17: 0.35 | AX17: 0.35 | AY17: 0.35 | AZ17: 0.35 | BA17: 0.35 | BB17: 0.35 | BC17: 0.35 | BD17: 0.35 | BE17: 0.35 | BF17: 0.35 | BG17: 0.35 | BH17: 0.35 | BI17: 0.35 | BJ17: 0.35 | BK17: 0.35 | BL17: 0.35 | BM17: 0.35 | BN17: 0.35 | BO17: 0.35 | BP17: 0.35 | BQ17: 0.35
B18: Directors Ees NIC | J18: 0.05 | K18: 0.05 | L18: 0.05 | M18: 0.05 | N18: 0.05 | O18: 0.05 | P18: 0.05 | Q18: 0.05 | R18: 0.05 | S18: 0.05 | T18: 0.05 | U18: 0.05 | V18: 0.05 | W18: 0.05 | X18: 0.05 | Y18: 0.05 | Z18: 0.05 | AA18: 0.05 | AB18: 0.05 | AC18: 0.05 | AD18: 0.05 | AE18: 0.05 | AF18: 0.05 | AG18: 0.05 | AH18: 0.05 | AI18: 0.05 | AJ18: 0.05 | AK18: 0.05 | AL18: 0.05 | AM18: 0.05 | AN18: 0.05 | AO18: 0.05 | AP18: 0.05 | AQ18: 0.05 | AR18: 0.05 | AS18: 0.05 | AT18: 0.05 | AU18: 0.05 | AV18: 0.05 | AW18: 0.05 | AX18: 0.05 | AY18: 0.05 | AZ18: 0.05 | BA18: 0.05 | BB18: 0.05 | BC18: 0.05 | BD18: 0.05 | BE18: 0.05 | BF18: 0.05 | BG18: 0.05 | BH18: 0.05 | BI18: 0.05 | BJ18: 0.05 | BK18: 0.05 | BL18: 0.05 | BM18: 0.05 | BN18: 0.05 | BO18: 0.05 | BP18: 0.05 | BQ18: 0.05
B19: Directors Ers Nic | J19: 0.14 | K19: 0.14 | L19: 0.14 | M19: 0.14 | N19: 0.14 | O19: 0.14 | P19: 0.14 | Q19: 0.14 | R19: 0.14 | S19: 0.14 | T19: 0.14 | U19: 0.14 | V19: 0.14 | W19: 0.14 | X19: 0.14 | Y19: 0.14 | Z19: 0.14 | AA19: 0.14 | AB19: 0.14 | AC19: 0.14 | AD19: 0.14 | AE19: 0.14 | AF19: 0.14 | AG19: 0.14 | AH19: 0.14 | AI19: 0.14 | AJ19: 0.14 | AK19: 0.14 | AL19: 0.14 | AM19: 0.14 | AN19: 0.14 | AO19: 0.14 | AP19: 0.14 | AQ19: 0.14 | AR19: 0.14 | AS19: 0.14 | AT19: 0.14 | AU19: 0.14 | AV19: 0.14 | AW19: 0.14 | AX19: 0.14 | AY19: 0.14 | AZ19: 0.14 | BA19: 0.14 | BB19: 0.14 | BC19: 0.14 | BD19: 0.14 | BE19: 0.14 | BF19: 0.14 | BG19: 0.14 | BH19: 0.14 | BI19: 0.14 | BJ19: 0.14 | BK19: 0.14 | BL19: 0.14 | BM19: 0.14 | BN19: 0.14 | BO19: 0.14 | BP19: 0.14 | BQ19: 0.14
B20: Directors Pension | J20: 0.03 | K20: 0.03 | L20: 0.03 | M20: 0.03 | N20: 0.03 | O20: 0.03 | P20: 0.03 | Q20: 0.03 | R20: 0.03 | S20: 0.03 | T20: 0.03 | U20: 0.03 | V20: 0.03 | W20: 0.03 | X20: 0.03 | Y20: 0.03 | Z20: 0.03 | AA20: 0.03 | AB20: 0.03 | AC20: 0.03 | AD20: 0.03 | AE20: 0.03 | AF20: 0.03 | AG20: 0.03 | AH20: 0.03 | AI20: 0.03 | AJ20: 0.03 | AK20: 0.03 | AL20: 0.03 | AM20: 0.03 | AN20: 0.03 | AO20: 0.03 | AP20: 0.03 | AQ20: 0.03 | AR20: 0.03 | AS20: 0.03 | AT20: 0.03 | AU20: 0.03 | AV20: 0.03 | AW20: 0.03 | AX20: 0.03 | AY20: 0.03 | AZ20: 0.03 | BA20: 0.03 | BB20: 0.03 | BC20: 0.03 | BD20: 0.03 | BE20: 0.03 | BF20: 0.03 | BG20: 0.03 | BH20: 0.03 | BI20: 0.03 | BJ20: 0.03 | BK20: 0.03 | BL20: 0.03 | BM20: 0.03 | BN20: 0.03 | BO20: 0.03 | BP20: 0.03 | BQ20: 0.03
... B27: Corporation Tax | J27: 0.25 | K27: 0.25 | L27: 0.25 | M27: 0.25 | N27: 0.25 | O27: 0.25 | P27: 0.25 | Q27: 0.25 | R27: 0.25 | S27: 0.25 | T27: 0.25 | U27: 0.25 | V27: 0.25 | W27: 0.25 | X27: 0.25 | Y27: 0.25 | Z27: 0.25 | AA27: 0.25 | AB27: 0.25 | AC27: 0.25 | AD27: 0.25 | AE27: 0.25 | AF27: 0.25 | AG27: 0.25 | AH27: 0.25 | AI27: 0.25 | AJ27: 0.25 | AK27: 0.25 | AL27: 0.25 | AM27: 0.25 | AN27: 0.25 | AO27: 0.25 | AP27: 0.25 | AQ27: 0.25 | AR27: 0.25 | AS27: 0.25 | AT27: 0.25 | AU27: 0.25 | AV27: 0.25 | AW27: 0.25 | AX27: 0.25 | AY27: 0.25 | AZ27: 0.25 | BA27: 0.25 | BB27: 0.25 | BC27: 0.25 | BD27: 0.25 | BE27: 0.25 | BF27: 0.25 | BG27: 0.25 | BH27: 0.25 | BI27: 0.25 | BJ27: 0.25 | BK27: 0.25 | BL27: 0.25 | BM27: 0.25 | BN27: 0.25 | BO27: 0.25 | BP27: 0.25 | BQ27: 0.25
B29: Sales Forecast
B31: ISP Funds Capex
B32: New Screens | J32: 30 | K32: 30 | M32: 30 | N32: 30 | O32: 30 | P32: 60 | Q32: 0 | R32: 0 | S32: 0 | T32: 0 | U32: 0 | V32: 0 | W32: 30 | X32: 30 | Y32: 30 | Z32: 30 | AA32: 30 | AB32: 30 | AC32: 30 | AD32: 30 | AE32: 30 | AF32: 30 | AG32: 30 | AH32: 36 | AI32: 36 | AJ32: 36 | AK32: 36 | AL32: 36 | AM32: 36 | AN32: 36 | AO32: 36 | AP32: 36 | AQ32: 36 | AR32: 36 | AS32: 36 | AT32: 43 | AU32: 43 | AV32: 43 | AW32: 43 | AX32: 43 | AY32: 43 | AZ32: 43 | BA32: 43 | BB32: 43 | BC32: 43 | BD32: 43 | BE32: 43 | BF32: 52 | BG32: 52 | BH32: 52 | BI32: 52 | BJ32: 52 | BK32: 52 | BL32: 52 | BM32: 52 | BN32: 52 | BO32: 52 | BP32: 52 | BQ32: 52
B33: Live Screens | J33: 90 | K33: =J33+K32 -> 120 | L33: =K33+L32 -> 120 | M33: =L33+M32 -> 150 | N33: =M33+N32 -> 180 | O33: 240 | P33: =O33+P32 -> 300 | Q33: =P33+Q32 -> 300 | R33: =Q33+R32 -> 300 | S33: =R33+S32 -> 300 | T33: =S33+T32 -> 300 | U33: =T33+U32 -> 300 | V33: =U33+V32 -> 300 | W33: =V33+W32 -> 330 | ... BQ33: =BP33+BQ32 -> 2202
B35: SCCI
B36: New Screens | J36: 0 | K36: 0 | L36: 0 | M36: 0 | N36: 0 | O36: 0 | P36: 0 | Q36: 0 | R36: 0 | S36: 0 | T36: 20 | U36: 20 | V36: 20 | W36: 20 | X36: 20 | Y36: 20 | Z36: 20 | AA36: 20 | AB36: 20 | AC36: 20 | AD36: 20 | AE36: 20 | AF36: 20 | AG36: 20 | AH36: 24 | AI36: 24 | AJ36: 24 | AK36: 24 | AL36: 24 | AM36: 24 | AN36: 24 | AO36: 24 | AP36: 24 | AQ36: 24 | AR36: 24 | AS36: 24 | AT36: 28 | AU36: 28 | AV36: 28 | AW36: 28 | AX36: 28 | AY36: 28 | AZ36: 28 | BA36: 28 | BB36: 28 | BC36: 28 | BD36: 28 | BE36: 28 | BF36: 32 | BG36: 32 | BH36: 32 | BI36: 32 | BJ36: 32 | BK36: 32 | BL36: 32 | BM36: 32 | BN36: 32 | BO36: 32 | BP36: 32 | BQ36: 32
B37: Live Screens | J37: 0 | K37: =J37+K36 -> 0 | L37: =K37+L36 -> 0 | M37: =L37+M36 -> 0 | N37: =M37+N36 -> 0 | O37: =N37+O36 -> 0 | P37: =O37+P36 -> 0 | Q37: =P37+Q36 -> 0 | R37: =Q37+R36 -> 0 | ... BQ37: =BP37+BQ36 -> 1288
B39: ISP Funds £0 Capex
B40: New Screens | J40: 0 | K40: 0 | L40: 0 | M40: 0 | N40: 0 | O40: 0 | P40: 0 | Q40: 0 | R40: 0 | S40: 2 | T40: 10 | U40: 10 | V40: 10 | W40: 20 | X40: 20 | Y40: 20 | Z40: 20 | AA40: 20 | AB40: 20 | AC40: 20 | AD40: 20 | AE40: 20 | AF40: 20 | AG40: 20 | AH40: 24 | AI40: 24 | AJ40: 24 | AK40: 24 | AL40: 24 | AM40: 24 | AN40: 24 | AO40: 24 | AP40: 24 | AQ40: 24 | AR40: 24 | AS40: 24 | AT40: 28 | AU40: 28 | AV40: 28 | AW40: 28 | AX40: 28 | AY40: 28 | AZ40: 28 | BA40: 28 | BB40: 28 | BC40: 28 | BD40: 28 | BE40: 28 | BF40: 32 | BG40: 32 | BH40: 32 | BI40: 32 | BJ40: 32 | BK40: 32 | BL40: 32 | BM40: 32 | BN40: 32 | BO40: 32 | BP40: 32 | BQ40: 32
B41: Live Screens | J41: 0 | K41: =J41+K40 -> 0 | L41: =K41+L40 -> 0 | M41: =L41+M40 -> 0 | N41: =M41+N40 -> 0 | O41: =N41+O40 -> 0 | P41: =O41+P40 -> 0 | Q41: =P41+Q40 -> 0 | R41: =Q41+R40 -> 0 | ... BQ41: =BP41+BQ40 -> 1260
B43: Other
B44: New Screens | J44: 0 | K44: 0 | L44: 0 | M44: 0 | N44: 0 | O44: 0 | P44: 0 | Q44: 0 | R44: 0 | S44: 0 | T44: 0 | U44: 0 | V44: 0 | W44: 0 | X44: 0 | Y44: 0 | Z44: 0 | AA44: 0 | AB44: 0 | AC44: 0 | AD44: 0 | AE44: 0 | AF44: 0 | AG44: 0 | AH44: 0 | AI44: 0 | AJ44: 0 | AK44: 0 | AL44: 0 | AM44: 0 | AN44: 0 | AO44: 0 | AP44: 0 | AQ44: 0 | AR44: 0 | AS44: 0 | AT44: 0 | AU44: 0 | AV44: 0 | AW44: 0 | AX44: 0 | AY44: 0 | AZ44: 0 | BA44: 0 | BB44: 0 | BC44: 0 | BD44: 0 | BE44: 0 | BF44: 0 | BG44: 0 | BH44: 0 | BI44: 0 | BJ44: 0 | BK44: 0 | BL44: 0 | BM44: 0 | BN44: 0 | BO44: 0 | BP44: 0 | BQ44: 0
B45: Live Screens | J45: 0 | K45: =J45+K44 -> 0 | L45: =K45+L44 -> 0 | M45: =L45+M44 -> 0 | N45: =M45+N44 -> 0 | O45: =N45+O44 -> 0 | P45: =O45+P44 -> 0 | Q45: =P45+Q44 -> 0 | R45: =Q45+R44 -> 0 | ... BQ45: =BP45+BQ44 -> 0
B49: Sales Assumptions
B50: ISP Funds Capex - one off revenue
B51: Revenue - new screens | J51: 1000 | K51: 1000 | L51: 1000 | M51: 1000 | N51: 1000 | O51: 1000 | P51: 1000 | Q51: 1000 | R51: 1000 | S51: 1000 | T51: 1000 | U51: 1000 | V51: 1000 | W51: 1000 | X51: 1000 | Y51: 1000 | Z51: 1000 | AA51: 1000 | AB51: 1000 | AC51: 1000 | AD51: 1000 | AE51: 1000 | AF51: 1000 | AG51: 1000 | AH51: =AG51+10%*AG51 -> 1100 | AI51: =AH51 -> 1100 | AJ51: =AI51 -> 1100 | AK51: =AJ51 -> 1100 | AL51: =AK51 -> 1100 | AM51: =AL51 -> 1100 | AN51: =AM51 -> 1100 | AO51: =AN51 -> 1100 | AP51: =AO51 -> 1100 | ... AS51: =AR51 -> 1100 | AT51: =AS51+10%*AS51 -> 1210 | AU51: =AT51 -> 1210 | AV51: =AU51 -> 1210 | AW51: =AV51 -> 1210 | AX51: =AW51 -> 1210 | AY51: =AX51 -> 1210 | AZ51: =AY51 -> 1210 | BA51: =AZ51 -> 1210 | BB51: =BA51 -> 1210 | ... BQ51: =BP51 -> 1210
B52: Revenue - set up and installation | J52: 750 | K52: 750 | L52: 750 | M52: 750 | N52: 750 | O52: 750 | P52: 750 | Q52: 750 | R52: 750 | S52: 750 | T52: 750 | U52: 750 | V52: 750 | W52: 750 | X52: 750 | Y52: 750 | Z52: 750 | AA52: 750 | AB52: 750 | AC52: 750 | AD52: 750 | AE52: 750 | AF52: 750 | AG52: 750 | AH52: =AG52+10%*AG52 -> 825 | AI52: =AH52 -> 825 | AJ52: =AI52 -> 825 | AK52: =AJ52 -> 825 | AL52: =AK52 -> 825 | AM52: =AL52 -> 825 | AN52: =AM52 -> 825 | AO52: =AN52 -> 825 | AP52: =AO52 -> 825 | ... AS52: =AR52 -> 825 | AT52: =AS52+10%*AS52 -> 907.5 | AU52: =AT52 -> 907.5 | AV52: =AU52 -> 907.5 | AW52: =AV52 -> 907.5 | AX52: =AW52 -> 907.5 | AY52: =AX52 -> 907.5 | AZ52: =AY52 -> 907.5 | BA52: =AZ52 -> 907.5 | BB52: =BA52 -> 907.5 | ... BQ52: =BP52 -> 907.5
B53: Revenue - Survey | J53: 250 | K53: 250 | L53: 250 | M53: 250 | N53: 250 | O53: 250 | P53: 250 | Q53: 250 | R53: 250 | S53: 250 | T53: 250 | U53: 250 | V53: 250 | W53: 250 | X53: 250 | Y53: 250 | Z53: 250 | AA53: 250 | AB53: 250 | AC53: 250 | AD53: 250 | AE53: 250 | AF53: 250 | AG53: 250 | AH53: =AG53+10%*AG53 -> 275 | AI53: =AH53 -> 275 | AJ53: =AI53 -> 275 | AK53: =AJ53 -> 275 | AL53: =AK53 -> 275 | AM53: =AL53 -> 275 | AN53: =AM53 -> 275 | AO53: =AN53 -> 275 | AP53: =AO53 -> 275 | ... AS53: =AR53 -> 275 | AT53: =AS53+10%*AS53 -> 302.5 | AU53: =AT53 -> 302.5 | AV53: =AU53 -> 302.5 | AW53: =AV53 -> 302.5 | AX53: =AW53 -> 302.5 | AY53: =AX53 -> 302.5 | AZ53: =AY53 -> 302.5 | BA53: =AZ53 -> 302.5 | BB53: =BA53 -> 302.5 | ... BQ53: =BP53 -> 302.5
B54: Revenue - Wall Mount | J54: 75 | K54: 75 | L54: 75 | M54: 75 | N54: 75 | O54: 75 | P54: 75 | Q54: 75 | R54: 75 | S54: 75 | T54: 75 | U54: 75 | V54: 75 | W54: 75 | X54: 75 | Y54: 75 | Z54: 75 | AA54: 75 | AB54: 75 | AC54: 75 | AD54: 75 | AE54: 75 | AF54: 75 | AG54: 75 | AH54: =AG54+10%*AG54 -> 82.5 | AI54: =AH54 -> 82.5 | AJ54: =AI54 -> 82.5 | AK54: =AJ54 -> 82.5 | AL54: =AK54 -> 82.5 | AM54: =AL54 -> 82.5 | AN54: =AM54 -> 82.5 | AO54: =AN54 -> 82.5 | AP54: =AO54 -> 82.5 | ... AS54: =AR54 -> 82.5 | AT54: =AS54+10%*AS54 -> 90.75 | AU54: =AT54 -> 90.75 | AV54: =AU54 -> 90.75 | AW54: =AV54 -> 90.75 | AX54: =AW54 -> 90.75 | AY54: =AX54 -> 90.75 | AZ54: =AY54 -> 90.75 | BA54: =AZ54 -> 90.75 | BB54: =BA54 -> 90.75 | ... BQ54: =BP54 -> 90.75
B55: Revenue - Software Set Up | J55: 50 | K55: 50 | L55: 50 | M55: 50 | N55: 50 | O55: 50 | P55: 50 | Q55: 50 | R55: 50 | S55: 50 | T55: 50 | U55: 50 | V55: 50 | W55: 50 | X55: 50 | Y55: 50 | Z55: 50 | AA55: 50 | AB55: 50 | AC55: 50 | AD55: 50 | AE55: 50 | AF55: 50 | AG55: 50 | AH55: =AG55+10%*AG55 -> 55 | AI55: =AH55 -> 55 | AJ55: =AI55 -> 55 | AK55: =AJ55 -> 55 | AL55: =AK55 -> 55 | AM55: =AL55 -> 55 | AN55: =AM55 -> 55 | AO55: =AN55 -> 55 | AP55: =AO55 -> 55 | ... AS55: =AR55 -> 55 | AT55: =AS55+10%*AS55 -> 60.5 | AU55: =AT55 -> 60.5 | AV55: =AU55 -> 60.5 | AW55: =AV55 -> 60.5 | AX55: =AW55 -> 60.5 | AY55: =AX55 -> 60.5 | AZ55: =AY55 -> 60.5 | BA55: =AZ55 -> 60.5 | BB55: =BA55 -> 60.5 | ... BQ55: =BP55 -> 60.5
B56: Revenue - Other | J56: 0 | K56: 0 | L56: 0 | M56: 0 | N56: 0 | O56: 0 | P56: 0 | Q56: 0 | R56: 0 | S56: 0 | T56: 0 | U56: 0 | V56: 0 | W56: 0 | X56: 0 | Y56: 0 | Z56: 0 | AA56: 0 | AB56: 0 | AC56: 0 | AD56: 0 | AE56: 0 | AF56: 0 | AG56: 0 | AH56: =AG56+10%*AG56 -> 0 | AI56: =AH56 -> 0 | AJ56: =AI56 -> 0 | AK56: =AJ56 -> 0 | AL56: =AK56 -> 0 | AM56: =AL56 -> 0 | AN56: =AM56 -> 0 | AO56: =AN56 -> 0 | AP56: =AO56 -> 0 | ... AS56: =AR56 -> 0 | AT56: =AS56+10%*AS56 -> 0 | AU56: =AT56 -> 0 | AV56: =AU56 -> 0 | AW56: =AV56 -> 0 | AX56: =AW56 -> 0 | AY56: =AX56 -> 0 | AZ56: =AY56 -> 0 | BA56: =AZ56 -> 0 | BB56: =BA56 -> 0 | ... BQ56: =BP56 -> 0
B58: ISP Funds Capex - Recurring Revenue
B59: Revenue - Software | J59: 75 | K59: 75 | L59: 75 | M59: 75 | N59: 75 | O59: 75 | P59: 75 | Q59: 75 | R59: 75 | S59: 75 | T59: 75 | U59: 75 | V59: 75 | W59: 75 | X59: 75 | Y59: 75 | Z59: 75 | AA59: 75 | AB59: 75 | AC59: 75 | AD59: 75 | AE59: 75 | AF59: 75 | AG59: 75 | AH59: =AG59+10%*AG59 -> 82.5 | AI59: =AH59 -> 82.5 | AJ59: =AI59 -> 82.5 | AK59: =AJ59 -> 82.5 | AL59: =AK59 -> 82.5 | AM59: =AL59 -> 82.5 | AN59: =AM59 -> 82.5 | AO59: =AN59 -> 82.5 | AP59: =AO59 -> 82.5 | ... AS59: =AR59 -> 82.5 | AT59: =AS59+10%*AS59 -> 90.75 | AU59: =AT59 -> 90.75 | AV59: =AU59 -> 90.75 | AW59: =AV59 -> 90.75 | AX59: =AW59 -> 90.75 | AY59: =AX59 -> 90.75 | AZ59: =AY59 -> 90.75 | BA59: =AZ59 -> 90.75 | BB59: =BA59 -> 90.75 | ... BQ59: =BP59 -> 90.75
B60: Per Month Rental 50 or below | J60: 0 | K60: 0 | L60: 0 | M60: 0 | N60: 0 | O60: 0 | P60: 0 | Q60: 0 | R60: 0 | S60: 0 | T60: 25 | U60: 25 | V60: 25 | W60: 25 | X60: 25 | Y60: 25 | Z60: 25 | AA60: 25 | AB60: 25 | AC60: 25 | AD60: 25 | AE60: 25 | AF60: 25 | AG60: 25 | AH60: =AG60+10%*AG60 -> 27.5 | AI60: =AH60 -> 27.5 | AJ60: =AI60 -> 27.5 | AK60: =AJ60 -> 27.5 | AL60: =AK60 -> 27.5 | AM60: =AL60 -> 27.5 | AN60: =AM60 -> 27.5 | AO60: =AN60 -> 27.5 | AP60: =AO60 -> 27.5 | ... AS60: =AR60 -> 27.5 | AT60: =AS60+10%*AS60 -> 30.25 | AU60: =AT60 -> 30.25 | AV60: =AU60 -> 30.25 | AW60: =AV60 -> 30.25 | AX60: =AW60 -> 30.25 | AY60: =AX60 -> 30.25 | AZ60: =AY60 -> 30.25 | BA60: =AZ60 -> 30.25 | BB60: =BA60 -> 30.25 | ... BQ60: =BP60 -> 30.25
...

Sheet Revenue
A1: Business 1
A2: Revenue | J2: =Timing!J2 -> 44986 | K2: =Timing!K2 -> 45017 | L2: =Timing!L2 -> 45047 | M2: =Timing!M2 -> 45078 | N2: =Timing!N2 -> 45108 | O2: =Timing!O2 -> 45139 | P2: =Timing!P2 -> 45170 | Q2: =Timing!Q2 -> 45200 | ... BQ2: =Timing!BQ2 -> 46784
J3: =Timing!J3 -> 45016 | K3: =Timing!K3 -> 45046 | L3: =Timing!L3 -> 45077 | M3: =Timing!M3 -> 45107 | N3: =Timing!N3 -> 45138 | O3: =Timing!O3 -> 45169 | P3: =Timing!P3 -> 45199 | Q3: =Timing!Q3 -> 45230 | ... BQ3: =Timing!BQ3 -> 46812
B4: Revenue Summary
B6: One Off Revenue
B7: =B36 -> Revenue - new screens | J7: =J38 -> 30000 | K7: =K38 -> 30000 | L7: =L38 -> 0 | M7: =M38 -> 30000 | N7: =N38 -> 30000 | O7: =O38 -> 30000 | P7: =P38 -> 60000 | Q7: =Q38 -> 0 | ... BQ7: =BQ38 -> 62920
B8: =B40 -> Revenue - set up and installation/Survey/wall mount | J8: =J42 -> 2250 | K8: =K42 -> 10050 | L8: =L42 -> 5620 | M8: =M42 -> 19673 | N8: =N42 -> 14774 | O8: =O42 -> 110844 | P8: =P42 -> 31714 | Q8: =Q42 -> 16000 | ... BQ8: =BQ42 -> 67639
B9: =B44 -> Revenue - software set-up | J9: =J46 -> 4550 | K9: =K46 -> 1500 | L9: =L46 -> 0 | M9: =M46 -> 0 | N9: =N46 -> 1500 | O9: =O46 -> 1500 | P9: =P46 -> 3000 | Q9: =Q46 -> 0 | ... BQ9: =BQ46 -> 3146
B10: =B48 -> Revenue - other | J10: =J50 -> 0 | K10: =K50 -> 0 | L10: =L50 -> 0 | M10: =M50 -> 0 | N10: =N50 -> 0 | O10: =O50 -> 1890 | P10: =P50 -> 12743 | Q10: =Q50 -> 1450 | ... BQ10: =BQ50 -> 0
B11: =B52 -> Revenue - SCCI initial set up | J11: =J54 -> 0 | K11: =K54 -> 0 | L11: =L54 -> 0 | M11: =M54 -> 0 | N11: =N54 -> 0 | O11: =O54 -> 0 | P11: =P54 -> 0 | Q11: =Q54 -> 0 | ... BQ11: =BQ54 -> 5808
B12: =B56 -> Revenue - ISP £0 Capex initial set up | J12: =J58 -> 0 | K12: =K58 -> 0 | L12: =L58 -> 0 | M12: =M58 -> 0 | N12: =N58 -> 0 | O12: =O58 -> 0 | P12: =P58 -> 0 | Q12: =Q58 -> 0 | ... BQ12: =BQ58 -> 11616
B15: Total One Off Revenue | J15: =SUM(J7:J14) -> 36800 | K15: =SUM(K7:K14) -> 41550 | L15: =SUM(L7:L14) -> 5620 | M15: =SUM(M7:M14) -> 49673 | N15: =SUM(N7:N14) -> 46274 | O15: =SUM(O7:O14) -> 144234 | P15: =SUM(P7:P14) -> 107457 | Q15: =SUM(Q7:Q14) -> 17450 | ... BQ15: =SUM(BQ7:BQ14) -> 151129
B18: Recurring Revenue
B19: =B64 -> Revenue - Software | J19: =J66 -> 0 | K19: =K66 -> 6750 | L19: =L66 -> 9000 | M19: =M66 -> 12750 | N19: =N66 -> 13500 | O19: =O66 -> 13500 | P19: =P66 -> 16275 | Q19: =Q66 -> 17175 | ... BQ19: =BQ66 -> 195112.5
B20: =B68 -> Revenue - Per month rental | J20: =J72 -> 0 | K20: =K72 -> 0 | L20: =L72 -> 0 | M20: =M72 -> 0 | N20: =N72 -> 0 | O20: =O72 -> 0 | P20: =P72 -> 0 | Q20: =Q72 -> 0 | ... BQ20: =BQ72 -> 84548.75
B21: =B74 -> Revenue - Media and Advertising | J21: =J76 -> 0 | K21: =K76 -> 0 | L21: =L76 -> 0 | M21: =M76 -> 0 | N21: =N76 -> 0 | O21: =O76 -> 0 | P21: =P76 -> 0 | Q21: =Q76 -> 0 | ... BQ21: =BQ76 -> 195112.5
B22: =B98 -> Revenue - Managing Agent | J22: =J100 -> 0 | K22: =K100 -> 0 | L22: =L100 -> 0 | M22: =M100 -> 0 | N22: =N100 -> 0 | O22: =O100 -> 0 | P22: =P100 -> 0 | Q22: =Q100 -> 0 | ... BQ22: =BQ100 -> 228690
B23: =B78 -> Revenue - SCCI Software rental | J23: =J80 -> 0 | K23: =K80 -> 0 | L23: =L80 -> 0 | M23: =M80 -> 0 | N23: =N80 -> 0 | O23: =O80 -> 0 | P23: =P80 -> 0 | Q23: =Q80 -> 0 | ... BQ23: =BQ80 -> 155848
B24: =B82 -> Revenue - SCCI Media and Advertising | J24: =J84 -> 0 | K24: =K84 -> 0 | L24: =L84 -> 0 | M24: =M84 -> 0 | N24: =N84 -> 0 | O24: =O84 -> 0 | P24: =P84 -> 0 | Q24: =Q84 -> 0 | ... BQ24: =BQ84 -> 75988
B25: =B86 -> Revenue - ISP £0 Capex Software rental | J25: =J88 -> 0 | K25: =K88 -> 0 | L25: =L88 -> 0 | M25: =M88 -> 0 | N25: =N88 -> 0 | O25: =O88 -> 0 | P25: =P88 -> 0 | Q25: =Q88 -> 0 | ... BQ25: =BQ88 -> 190575
B26: =B90 -> Revenue - ISP £0 Capex Media and Advertising | J26: =J92 -> 0 | K26: =K92 -> 0 | L26: =L92 -> 0 | M26: =M92 -> 0 | N26: =N92 -> 0 | O26: =O92 -> 0 | P26: =P92 -> 0 | Q26: =Q92 -> 0 | ... BQ26: =BQ92 -> 111441
B27: =B94 -> Revenue - Other Media and Advertising | J27: =J96 -> 0 | K27: =K96 -> 0 | L27: =L96 -> 0 | M27: =M96 -> 0 | N27: =N96 -> 0 | O27: =O96 -> 0 | P27: =P96 -> 0 | Q27: =Q96 -> 0 | ... BQ27: =BQ96 -> 0
B28: =B102 -> Revenue - ISP £0 Capex Managing Agent | J28: =J104 -> 0 | K28: =K104 -> 0 | L28: =L104 -> 0 | M28: =M104 -> 0 | N28: =N104 -> 0 | O28: =O104 -> 0 | P28: =P104 -> 0 | Q28: =Q104 -> 0 | ... BQ28: =BQ104 -> 129228
B31: Total Recurring Revenue | J31: =SUM(J19:J30) -> 0 | K31: =SUM(K19:K30) -> 6750 | L31: =SUM(L19:L30) -> 9000 | M31: =SUM(M19:M30) -> 12750 | N31: =SUM(N19:N30) -> 13500 | O31: =SUM(O19:O30) -> 13500 | P31: =SUM(P19:P30) -> 16275 | Q31: =SUM(Q19:Q30) -> 17175 | ... BQ31: =SUM(BQ19:BQ30) -> 1366543.8
A33: Total
B35: One Off Revenue
B36: Revenue - new screens | J36: 30000 | K36: 30000 | L36: 0 | M36: 30000 | N36: 30000 | O36: 30000 | P36: 60000 | Q36: 0 | R36: =Inputs!R32*Inputs!R51 -> 0 | S36: =Inputs!S32*Inputs!S51 -> 0 | T36: =Inputs!T32*Inputs!T51 -> 0 | U36: =Inputs!U32*Inputs!U51 -> 0 | V36: =Inputs!V32*Inputs!V51 -> 0 | W36: =Inputs!W32*Inputs!W51 -> 30000 | X36: =Inputs!X32*Inputs!X51 -> 30000 | Y36: =Inputs!Y32*Inputs!Y51 -> 30000 | ... BQ36: =Inputs!BQ32*Inputs!BQ51 -> 62920
B38: Total | J38: =SUM(J36:J37) -> 30000 | K38: =SUM(K36:K37) -> 30000 | L38: =SUM(L36:L37) -> 0 | M38: =SUM(M36:M37) -> 30000 | N38: =SUM(N36:N37) -> 30000 | O38: =SUM(O36:O37) -> 30000 | P38: =SUM(P36:P37) -> 60000 | Q38: =SUM(Q36:Q37) -> 0 | ... BQ38: =SUM(BQ36:BQ37) -> 62920
B40: Revenue - set up and installation/Survey/wall mount | J40: 2250 | K40: =2250+7800 -> 10050 | L40: 5620 | M40: =2250+17423 -> 19673 | N40: =2250+12524 -> 14774 | O40: =2250+78094+30500 -> 110844 | P40: 31714 | Q40: 16000 | R40: 15750 | S40: =Inputs!S32*(Inputs!S52+Inputs!S53+Inputs!S54) -> 0 | T40: =Inputs!T32*(Inputs!T52+Inputs!T53+Inputs!T54) -> 0 | U40: =Inputs!U32*(Inputs!U52+Inputs!U53+Inputs!U54) -> 0 | V40: =Inputs!V32*(Inputs!V52+Inputs!V53+Inputs!V54) -> 0 | W40: =Inputs!W32*(Inputs!W52+Inputs!W53+Inputs!W54) -> 32250 | X40: =Inputs!X32*(Inputs!X52+Inputs!X53+Inputs!X54) -> 32250 | Y40: =Inputs!Y32*(Inputs!Y52+Inputs!Y53+Inputs!Y54) -> 32250 | Z40: =Inputs!Z32*(Inputs!Z52+Inputs!Z53+Inputs!Z54) -> 32250 | ... BQ40: =Inputs!BQ32*(Inputs!BQ52+Inputs!BQ53+Inputs!BQ54) -> 67639
B42: Total | J42: =SUM(J40:J41) -> 2250 | K42: =SUM(K40:K41) -> 10050 | L42: =SUM(L40:L41) -> 5620 | M42: =SUM(M40:M41) -> 19673 | N42: =SUM(N40:N41) -> 14774 | O42: =SUM(O40:O41) -> 110844 | P42: =SUM(P40:P41) -> 31714 | Q42: =SUM(Q40:Q41) -> 16000 | ... BQ42: =SUM(BQ40:BQ41) -> 67639
B44: Revenue - software set-up | J44: 4550 | K44: 1500 | L44: 0 | M44: 0 | N44: 1500 | O44: 1500 | P44: =Inputs!P32*Inputs!P55 -> 3000 | Q44: 0 | R44: =Inputs!R32*Inputs!R55 -> 0 | S44: =Inputs!S32*Inputs!S55 -> 0 | T44: =Inputs!T32*Inputs!T55 -> 0 | U44: =Inputs!U32*Inputs!U55 -> 0 | V44: =Inputs!V32*Inputs!V55 -> 0 | W44: =Inputs!W32*Inputs!W55 -> 1500 | X44: =Inputs!X32*Inputs!X55 -> 1500 | Y44: =Inputs!Y32*Inputs!Y55 -> 1500 | ... BQ44: =Inputs!BQ32*Inputs!BQ55 -> 3146
B46: Total | J46: =SUM(J44:J45) -> 4550 | K46: =SUM(K44:K45) -> 1500 | L46: =SUM(L44:L45) -> 0 | M46: =SUM(M44:M45) -> 0 | N46: =SUM(N44:N45) -> 1500 | O46: =SUM(O44:O45) -> 1500 | P46: =SUM(P44:P45) -> 3000 | Q46: =SUM(Q44:Q45) -> 0 | ... BQ46: =SUM(BQ44:BQ45) -> 3146
B48: Revenue - other | J48: =Inputs!J56 -> 0 | K48: =Inputs!K56 -> 0 | L48: =Inputs!L56 -> 0 | M48: =Inputs!M56 -> 0 | N48: =Inputs!N56 -> 0 | O48: 1890 | P48: 12743 | Q48: 1450 | R48: =Inputs!R56 -> 0 | S48: =Inputs!S56 -> 0 | T48: =Inputs!T56 -> 0 | U48: =Inputs!U56 -> 0 | V48: =Inputs!V56 -> 0 | W48: =Inputs!W56 -> 0 | X48: =Inputs!X56 -> 0 | Y48: =Inputs!Y56 -> 0 | ... BQ48: =Inputs!BQ56 -> 0
B50: Total | J50: =SUM(J48:J49) -> 0 | K50: =SUM(K48:K49) -> 0 | L50: =SUM(L48:L49) -> 0 | M50: =SUM(M48:M49) -> 0 | N50: =SUM(N48:N49) -> 0 | O50: =SUM(O48:O49) -> 1890 | P50: =SUM(P48:P49) -> 12743 | Q50: =SUM(Q48:Q49) -> 1450 | ... BQ50: =SUM(BQ48:BQ49) -> 0
B52: Revenue - SCCI initial set up | J52: =Inputs!J36*Inputs!J68 -> 0 | K52: =Inputs!K36*Inputs!K68 -> 0 | L52: =Inputs!L36*Inputs!L68 -> 0 | M52: =Inputs!M36*Inputs!M68 -> 0 | N52: =Inputs!N36*Inputs!N68 -> 0 | O52: =Inputs!O36*Inputs!O68 -> 0 | P52: =Inputs!P36*Inputs!P68 -> 0 | Q52: =Inputs!Q36*Inputs!Q68 -> 0 | ... BQ52: =Inputs!BQ36*Inputs!BQ68 -> 5808
B54: Total | J54: =SUM(J52:J53) -> 0 | K54: =SUM(K52:K53) -> 0 | L54: =SUM(L52:L53) -> 0 | M54: =SUM(M52:M53) -> 0 | N54: =SUM(N52:N53) -> 0 | O54: =SUM(O52:O53) -> 0 | P54: =SUM(P52:P53) -> 0 | Q54: =SUM(Q52:Q53) -> 0 | ... BQ54: =SUM(BQ52:BQ53) -> 5808
B56: Revenue - ISP £0 Capex initial set up | J56: =Inputs!J40*Inputs!J75 -> 0 | K56: =Inputs!K40*Inputs!K75 -> 0 | L56: =Inputs!L40*Inputs!L75 -> 0 | M56: =Inputs!M40*Inputs!M75 -> 0 | N56: =Inputs!N40*Inputs!N75 -> 0 | O56: =Inputs!O40*Inputs!O75 -> 0 | P56: =Inputs!P40*Inputs!P75 -> 0 | Q56: =Inputs!Q40*Inputs!Q75 -> 0 | ... BQ56: =Inputs!BQ40*Inputs!BQ75 -> 11616
B58: Total | J58: =SUM(J56:J57) -> 0 | K58: =SUM(K56:K57) -> 0 | L58: =SUM(L56:L57) -> 0 | M58: =SUM(M56:M57) -> 0 | N58: =SUM(N56:N57) -> 0 | O58: =SUM(O56:O57) -> 0 | P58: =SUM(P56:P57) -> 0 | Q58: =SUM(Q56:Q57) -> 0 | ... BQ58: =SUM(BQ56:BQ57) -> 11616
B63: Recurring Revenue
B64: Revenue - Software | J64: 0 | K64: 6750 | L64: 9000 | M64: 12750 | N64: 13500 | O64: 13500 | P64: 16275 | Q64: 17175 | R64: =Inputs!Q33*Inputs!R59 -> 22500 | S64: =Inputs!R33*Inputs!S59 -> 22500 | T64: =Inputs!S33*Inputs!T59 -> 22500 | U64: =Inputs!T33*Inputs!U59 -> 22500 | V64: =Inputs!U33*Inputs!V59 -> 22500 | W64: =Inputs!V33*Inputs!W59 -> 22500 | X64: =Inputs!W33*Inputs!X59 -> 24750 | Y64: =Inputs!X33*Inputs!Y59 -> 27000 | ... BQ64: =Inputs!BP33*Inputs!BQ59 -> 195112.5
...

Sheet COS and Overheads
A1: Business 1
A2: Cost of Sales and Overheads | J2: =Timing!J2 -> 44986 | K2: =Timing!K2 -> 45017 | L2: =Timing!L2 -> 45047 | M2: =Timing!M2 -> 45078 | N2: =Timing!N2 -> 45108 | O2: =Timing!O2 -> 45139 | P2: =Timing!P2 -> 45170 | Q2: =Timing!Q2 -> 45200 | ... BQ2: =Timing!BQ2 -> 46784
J3: =Timing!J3 -> 45016 | K3: =Timing!K3 -> 45046 | L3: =Timing!L3 -> 45077 | M3: =Timing!M3 -> 45107 | N3: =Timing!N3 -> 45138 | O3: =Timing!O3 -> 45169 | P3: =Timing!P3 -> 45199 | Q3: =Timing!Q3 -> 45230 | ... BQ3: =Timing!BQ3 -> 46812
B5: COS Summary
B6: =B52 -> ISP capex - Cost of screens | J6: =J54 -> 18000 | K6: =K54 -> 0 | L6: =L54 -> 18000 | M6: =M54 -> 18000 | N6: =N54 -> 18000 | O6: =O54 -> 18000 | P6: =P54 -> 40692 | Q6: =Q54 -> 0 | ... BQ6: =BQ54 -> 32396
B7: =B57 -> ISP capex - Screen Set up and Installation | J7: =J59 -> 0 | K7: =K59 -> 7364 | L7: =L59 -> 8896 | M7: =M59 -> 5055 | N7: =N59 -> 10047 | O7: =O59 -> 60033 | P7: =P59 -> 17604 | Q7: =Q59 -> 3285 | ... BQ7: =BQ59 -> 31200
B8: =B62 -> ISP capex - Screen Wall mount | J8: =J64 -> 1425 | K8: =K64 -> 0 | L8: =L64 -> 1425 | M8: =M64 -> 1500 | N8: =N64 -> 1500 | O8: =O64 -> 1425 | P8: =P64 -> 3207 | Q8: =Q64 -> 0 | ... BQ8: =BQ64 -> 2496
B9: =B67 -> ISP capex - Screen Survey cost | J9: =J69 -> 0 | K9: =K69 -> 0 | L9: =L69 -> 0 | M9: =M69 -> 0 | N9: =N69 -> 0 | O9: =O69 -> 21800 | P9: =P69 -> 476 | Q9: =Q69 -> 4000 | ... BQ9: =BQ69 -> 10400
B10: =B72 -> ISP capex - Software charge | J10: =J74 -> 0 | K10: =K74 -> 0 | L10: =L74 -> 484 | M10: =M74 -> 484 | N10: =N74 -> 1760 | O10: =O74 -> 1804 | P10: =P74 -> 2266 | Q10: =Q74 -> 3344 | ... BQ10: =BQ74 -> 49545
B11: =B77 -> ISP capex - Other costs | J11: =J79 -> 0 | K11: =K79 -> 0 | L11: =L79 -> 0 | M11: =M79 -> 0 | N11: =N79 -> 0 | O11: =O79 -> 345 | P11: =P79 -> 45 | Q11: =Q79 -> 0 | ... BQ11: =BQ79 -> 0
B12: =B82 -> ISP capex - Media and Advertising | J12: =J84 -> 0 | K12: =K84 -> 0 | L12: =L84 -> 0 | M12: =M84 -> 0 | N12: =N84 -> 0 | O12: =O84 -> 0 | P12: =P84 -> 0 | Q12: =Q84 -> 0 | ... BQ12: =BQ84 -> 129000
B13: =B87 -> SCCI - Software charge | J13: =J89 -> 0 | K13: =K89 -> 0 | L13: =L89 -> 0 | M13: =M89 -> 0 | N13: =N89 -> 0 | O13: =O89 -> 0 | P13: =P89 -> 0 | Q13: =Q89 -> 0 | ... BQ13: =BQ89 -> 28980
B14: =B92 -> SCCI - 5g ongoing cost | J14: =J94 -> 0 | K14: =K94 -> 0 | L14: =L94 -> 0 | M14: =M94 -> 0 | N14: =N94 -> 0 | O14: =O94 -> 0 | P14: =P94 -> 0 | Q14: =Q94 -> 0 | ... BQ14: =BQ94 -> 3864
B15: =B97 -> ISP Funds £0 Capex - Software charge | J15: =J99 -> 0 | K15: =K99 -> 0 | L15: =L99 -> 0 | M15: =M99 -> 0 | N15: =N99 -> 0 | O15: =O99 -> 0 | P15: =P99 -> 0 | Q15: =Q99 -> 0 | ... BQ15: =BQ99 -> 28350
B16: =B102 -> ISP Funds £0 Capex - 5g ongoing cost | J16: =J104 -> 0 | K16: =K104 -> 0 | L16: =L104 -> 0 | M16: =M104 -> 0 | N16: =N104 -> 0 | O16: =O104 -> 0 | P16: =P104 -> 0 | Q16: =Q104 -> 0 | ... BQ16: =BQ104 -> 3780
B17: =B107 -> Other - Software charge | J17: =J109 -> 0 | K17: =K109 -> 0 | L17: =L109 -> 0 | M17: =M109 -> 0 | N17: =N109 -> 0 | O17: =O109 -> 0 | P17: =P109 -> 0 | Q17: =Q109 -> 0 | ... BQ17: =BQ109 -> 0
B18: =B112 -> Other - 5g ongoing cost | J18: =J114 -> 0 | K18: =K114 -> 0 | L18: =L114 -> 0 | M18: =M114 -> 0 | N18: =N114 -> 0 | O18: =O114 -> 0 | P18: =P114 -> 0 | Q18: =Q114 -> 0 | ... BQ18: =BQ114 -> 0
B19: =B117 -> Other - Freeholder cost | J19: =J119 -> 0 | K19: =K119 -> 0 | L19: =L119 -> 0 | M19: =M119 -> 0 | N19: =N119 -> 0 | O19: =O119 -> 0 | P19: =P119 -> 0 | Q19: =Q119 -> 0 | ... BQ19: =BQ119 -> 173100
B25: Total COS | J25: =SUM(J6:J24) -> 19425 | K25: =SUM(K6:K24) -> 7364 | L25: =SUM(L6:L24) -> 28805 | M25: =SUM(M6:M24) -> 25039 | N25: =SUM(N6:N24) -> 31307 | O25: =SUM(O6:O24) -> 103407 | P25: =SUM(P6:P24) -> 64290 | Q25: =SUM(Q6:Q24) -> 10629 | ... BQ25: =SUM(BQ6:BQ24) -> 493111
B28: Overhead Summary
B29: Rent | J29: =J137 -> 0 | K29: =K137 -> 0 | L29: =L137 -> 0 | M29: =M137 -> 0 | N29: =N137 -> 0 | O29: =O137 -> 0 | P29: =P137 -> 0 | Q29: =Q137 -> 0 | ... BQ29: =BQ137 -> 2500
B30: Rates | J30: =J143 -> 0 | K30: =K143 -> 0 | L30: =L143 -> 0 | M30: =M143 -> 0 | N30: =N143 -> 0 | O30: =O143 -> 0 | P30: =P143 -> 0 | Q30: =Q143 -> 0 | ... BQ30: =BQ143 -> 0
B31: Recruitment Costs | J31: =J149 -> 0 | K31: =K149 -> 0 | L31: =L149 -> 0 | M31: =M149 -> 0 | N31: =N149 -> 0 | O31: =O149 -> 0 | P31: =P149 -> 0 | Q31: =Q149 -> 0 | ... BQ31: =BQ149 -> 0
B32: Repairs and maintenance | J32: =J155 -> 0 | K32: =K155 -> 0 | L32: =L155 -> 0 | M32: =M155 -> 0 | N32: =N155 -> 0 | O32: =O155 -> 0 | P32: =P155 -> 0 | Q32: =Q155 -> 0 | ... BQ32: =BQ155 -> 2156.25
B33: Insurance | J33: =J164 -> 0 | K33: =K164 -> 0 | L33: =L164 -> 0 | M33: =M164 -> 0 | N33: =N164 -> 0 | O33: =O164 -> 0 | P33: =P164 -> 0 | Q33: =Q164 -> 0 | ... BQ33: =BQ164 -> 3050
B34: Computer running costs | J34: =J172 -> 2575 | K34: =K172 -> 1500 | L34: =L172 -> 170 | M34: =M172 -> 2079 | N34: =N172 -> 0 | O34: =O172 -> 170 | P34: =P172 -> 0 | Q34: =Q172 -> 18850 | ... BQ34: =BQ172 -> 1270
B35: Travelling expenses | J35: =J178 -> 0 | K35: =K178 -> 399 | L35: =L178 -> 230 | M35: =M178 -> 156 | N35: =N178 -> 2199 | O35: =O178 -> 0 | P35: =P178 -> 0 | Q35: =Q178 -> 0 | ... BQ35: =BQ178 -> 7000
B36: Legal and professional fees | J36: =J184 -> 0 | K36: =K184 -> 0 | L36: =L184 -> 0 | M36: =M184 -> 0 | N36: =N184 -> 0 | O36: =O184 -> 0 | P36: =P184 -> 0 | Q36: =Q184 -> 0 | ... BQ36: =BQ184 -> 2000
B37: Consultancy | J37: =J190 -> 0 | K37: =K190 -> 0 | L37: =L190 -> 15000 | M37: =M190 -> 32550 | N37: =N190 -> 30000 | O37: =O190 -> 30000 | P37: =P190 -> 30000 | Q37: =Q190 -> 40368 | ... BQ37: =BQ190 -> 0
