Workbook

Sheet Consolidated P&L
B2: 45352 | C2: 45383 | D2: 45413 | E2: 45444 | F2: 45474 | G2: 45505 | H2: 45536 | I2: 45566 | J2: 45597 | K2: 45627 | L2: 45658 | M2: 45689 | N2: 45717 | O2: 45748 | P2: 45778 | Q2: 45809 | R2: 45839 | S2: 45870 | T2: 45901 | U2: 45931 | V2: 45962 | W2: 45992
B3: Actual | C3: Actual | D3: Actual | E3: Actual | F3: Actual | G3: FORECAST | H3: FORECAST | I3: FORECAST | J3: FORECAST | K3: FORECAST | L3: FORECAST | M3: FORECAST | N3: FORECAST | O3: FORECAST | P3: FORECAST | Q3: FORECAST | R3: FORECAST | S3: FORECAST | T3: FORECAST | U3: FORECAST | V3: FORECAST | W3: FORECAST
A4: Income
A5: New screens | B5: 0 | C5: 0 | D5: 0 | E5: 0 | F5: 0 | G5: 0 | H5: 0 | I5: ='Revenue summary'!E60 -> 4 | J5: ='Revenue summary'!F60 -> 17 | K5: ='Revenue summary'!G60 -> 17 | L5: ='Revenue summary'!H60 -> 17 | M5: ='Revenue summary'!I60 -> 17 | N5: ='Revenue summary'!J60 -> 0 | O5: ='Revenue summary'!K60 -> 18 | P5: ='Revenue summary'!L60 -> 18 | ... W5: ='Revenue summary'!S60 -> 0
A6: Live screens | B6: 210 | C6: 210 | D6: 210 | E6: 210 | F6: ='4th P&L'!G6+'Eris P&L'!G7 -> 210 | G6: =F6+G5 -> 210 | H6: =G6+H5 -> 210 | I6: =H6+I5 -> 214 | J6: =I6+J5 -> 231 | K6: =J6+K5 -> 248 | L6: =K6+L5 -> 265 | M6: =L6+M5 -> 282 | N6: =M6+N5 -> 282 | ... W6: =V6+W5 -> 468
A8: Revenue 1 - Software (annual upfront fee) | B8: 18475 | C8: 18475 | D8: 18475 | E8: 18475 | F8: 2689 | G8: ='Revenue summary'!C63 -> 0 | H8: ='Revenue summary'!D63 -> 32526 | I8: ='Revenue summary'!E63 -> 0 | J8: ='Revenue summary'!F63 -> 43806 | K8: ='Revenue summary'!G63 -> 27950 | L8: ='Revenue summary'!H63 -> 27950 | M8: ='Revenue summary'!I63 -> 27950 | N8: ='Revenue summary'!J63 -> 27950 | ... W8: ='Revenue summary'!S63 -> 27950
A9: Revenue 2 - Ad partner revenue | B9: 0 | C9: 0 | D9: 0 | E9: 0 | F9: 0 | G9: ='Revenue summary'!C64 -> 0 | H9: ='Revenue summary'!D64 -> 0 | I9: ='Revenue summary'!E64 -> 0 | J9: ='Revenue summary'!F64 -> 0 | K9: ='Revenue summary'!G64 -> 0 | L9: ='Revenue summary'!H64 -> 1250 | M9: ='Revenue summary'!I64 -> 7183.3333 | N9: ='Revenue summary'!J64 -> 9033.3333 | ... W9: ='Revenue summary'!S64 -> 15383.333
A10: Other Revenue
A16: Total Income | B16: =SUM(B8:B15) -> 18475 | C16: =SUM(C8:C15) -> 18475 | D16: =SUM(D8:D15) -> 18475 | E16: =SUM(E8:E15) -> 18475 | F16: =SUM(F8:F15) -> 2689 | G16: =SUM(G8:G15) -> 0 | H16: =SUM(H8:H15) -> 32526 | I16: =SUM(I8:I15) -> 0 | ... W16: =SUM(W8:W15) -> 43333.333
A18: Less Cost of Sales
A19: Direct costs | B19: 3458.65 | C19: 11847 | D19: 5696.27 | E19: 5484 | F19: 2574 | G19: ='Non Staff costs'!C13 -> 2560 | H19: ='Non Staff costs'!D13 -> 2560 | I19: ='Non Staff costs'!E13 -> 2560 | J19: ='Non Staff costs'!F13 -> 2560 | K19: ='Non Staff costs'!G13 -> 75 | L19: ='Non Staff costs'!H13 -> 150 | M19: ='Non Staff costs'!I13 -> 225 | N19: ='Non Staff costs'!J13 -> 300 | ... W19: ='Non Staff costs'!S13 -> 300
A20: Other Direct costs
A26: Staff Cost
A27: Commission/ Consultancy costs | B27: 6000 | C27: 6000 | D27: 6000 | E27: 6000 | F27: 0 | G27: ='Staff costs'!J2 -> 0 | H27: ='Staff costs'!K12 -> 9333.33 | I27: ='Staff costs'!L12 -> 9333.33 | J27: ='Staff costs'!M12 -> 9333.33 | K27: ='Staff costs'!N12 -> 12333.33 | L27: ='Staff costs'!O12 -> 12333.33 | M27: ='Staff costs'!P12 -> 12333.33 | N27: ='Staff costs'!Q12 -> 12333.33 | O27: ='Staff costs'!R12 -> 12333.33 | ... W27: ='Staff costs'!Z12 -> 12333.33
A28: Direct Wages | B28: =6070.82+181.97 -> 6252.79 | C28: =8012.54+199.13 -> 8211.67 | D28: =8589.74+366.9 -> 8956.64 | E28: 0 | F28: 0 | G28: ='Staff costs'!J10 -> 0 | H28: ='Staff costs'!K10 -> 0 | I28: ='Staff costs'!L10 -> 0 | J28: ='Staff costs'!M10 -> 3540 | K28: ='Staff costs'!N10 -> 3540 | L28: ='Staff costs'!O10 -> 3540 | M28: ='Staff costs'!P10 -> 3540 | N28: ='Staff costs'!Q10 -> 3540 | ... W28: ='Staff costs'!Z10 -> 3540
A30: Total Staff Cost | B30: =SUM(B27:B29) -> 12252.79 | C30: =SUM(C27:C29) -> 14211.67 | D30: =SUM(D27:D29) -> 14956.64 | E30: =SUM(E27:E29) -> 6000 | F30: =SUM(F27:F29) -> 0 | G30: =SUM(G27:G29) -> 0 | H30: =SUM(H27:H29) -> 9333.33 | I30: =SUM(I27:I29) -> 9333.33 | ... W30: =SUM(W27:W29) -> 15873.33
A32: Total Cost of Sales | B32: =SUM(B19:B24)+B30 -> 15711.44 | C32: =SUM(C19:C24)+C30 -> 26058.67 | D32: =SUM(D19:D24)+D30 -> 20652.91 | E32: =SUM(E19:E24)+E30 -> 11484 | F32: =SUM(F19:F24)+F30 -> 2574 | G32: =SUM(G19:G24)+G30 -> 2560 | H32: =SUM(H19:H24)+H30 -> 11893.33 | I32: =SUM(I19:I24)+I30 -> 11893.33 | ... W32: =SUM(W19:W24)+W30 -> 16173.33
A34: Gross Profit | B34: =(B16)-(B32) -> 2763.56 | C34: =(C16)-(C32) -> -7583.67 | D34: =(D16)-(D32) -> -2177.91 | E34: =(E16)-(E32) -> 6991 | F34: =(F16)-(F32) -> 115 | G34: =(G16)-(G32) -> -2560 | H34: =(H16)-(H32) -> 20632.67 | I34: =(I16)-(I32) -> -11893.33 | ... W34: =(W16)-(W32) -> 27160.003
A36: Less Operating Expenses
A38: Consulting | B38: 15550 | C38: 11800 | D38: 18500 | E38: 23319.33 | F38: 8666.66 | G38: ='Staff costs'!J7+'Staff costs'!J8 -> 0 | H38: ='Staff costs'!K7+'Staff costs'!K8 -> 0 | I38: ='Staff costs'!L7+'Staff costs'!L8 -> 0 | J38: ='Staff costs'!M7+'Staff costs'!M8 -> 0 | K38: ='Staff costs'!N7+'Staff costs'!N8 -> 0 | L38: ='Staff costs'!O7+'Staff costs'!O8 -> 0 | M38: ='Staff costs'!P7+'Staff costs'!P8 -> 0 | N38: ='Staff costs'!Q7+'Staff costs'!Q8 -> 0 | ... W38: ='Staff costs'!Z7+'Staff costs'!Z8 -> 10000
A39: Marketing/ Advertising | B39: 710 | C39: 1000 | D39: 300 | E39: 0 | F39: 0 | G39: ='Non Staff costs'!C18 -> 0 | H39: ='Non Staff costs'!D18 -> 0 | I39: ='Non Staff costs'!E18 -> 500 | J39: ='Non Staff costs'!F18 -> 500 | K39: ='Non Staff costs'!G18 -> 500 | L39: ='Non Staff costs'!H18 -> 500 | M39: ='Non Staff costs'!I18 -> 500 | N39: ='Non Staff costs'!J18 -> 500 | ... W39: ='Non Staff costs'!S18 -> 500
A40: Sundries/expenses/legals | B40: 148.95 | C40: 148.95 | D40: 6662.5 | E40: 148.95 | F40: 4950 | G40: ='Non Staff costs'!C19 -> 0 | H40: ='Non Staff costs'!D19 -> 0 | I40: ='Non Staff costs'!E19 -> 0 | J40: ='Non Staff costs'!F19 -> 0 | K40: ='Non Staff costs'!G19 -> 0 | L40: ='Non Staff costs'!H19 -> 0 | M40: ='Non Staff costs'!I19 -> 0 | N40: ='Non Staff costs'!J19 -> 0 | ... W40: ='Non Staff costs'!S19 -> 0
A41: Website costs | B41: 12675 | C41: 900 | D41: 450 | E41: 450 | F41: 0 | G41: ='Non Staff costs'!C20 -> 0 | H41: ='Non Staff costs'!D20 -> 0 | I41: ='Non Staff costs'!E20 -> 0 | J41: ='Non Staff costs'!F20 -> 5000 | K41: ='Non Staff costs'!G20 -> 5000 | L41: ='Non Staff costs'!H20 -> 5000 | M41: ='Non Staff costs'!I20 -> 5000 | N41: ='Non Staff costs'!J20 -> 5000 | ... W41: ='Non Staff costs'!S20 -> 5000
A42: Bookkeeping & Accountancy fees | B42: 1000 | C42: 500 | D42: 500 | E42: 500 | F42: 0 | G42: ='Non Staff costs'!C21 -> 0 | H42: ='Non Staff costs'!D21 -> 500 | I42: ='Non Staff costs'!E21 -> 500 | J42: ='Non Staff costs'!F21 -> 500 | K42: ='Non Staff costs'!G21 -> 500 | L42: ='Non Staff costs'!H21 -> 500 | M42: ='Non Staff costs'!I21 -> 1000 | N42: ='Non Staff costs'!J21 -> 1000 | ... W42: ='Non Staff costs'!S21 -> 1000
A43: Office costs/ rent | B43: 3000 | C43: 1500 | D43: 1500 | E43: 1500 | F43: 0 | G43: ='Non Staff costs'!C22 -> 1500 | H43: ='Non Staff costs'!D22 -> 1500 | I43: ='Non Staff costs'!E22 -> 1500 | J43: ='Non Staff costs'!F22 -> 1500 | K43: ='Non Staff costs'!G22 -> 1500 | L43: ='Non Staff costs'!H22 -> 1500 | M43: ='Non Staff costs'!I22 -> 1500 | N43: ='Non Staff costs'!J22 -> 1500 | ... W43: ='Non Staff costs'!S22 -> 1500
A44: Subscriptions | B44: 126.67 | C44: 126.67 | D44: 126.67 | E44: 126.67 | F44: 5 | G44: ='Non Staff costs'!C23 -> 150 | H44: ='Non Staff costs'!D23 -> 150 | I44: ='Non Staff costs'!E23 -> 150 | J44: ='Non Staff costs'!F23 -> 150 | K44: ='Non Staff costs'!G23 -> 150 | L44: ='Non Staff costs'!H23 -> 150 | M44: ='Non Staff costs'!I23 -> 150 | N44: ='Non Staff costs'!J23 -> 150 | ... W44: ='Non Staff costs'!S23 -> 150
A45: Postage, Freight & Courier | B45: ='HO P&L'!C38 -> 0 | C45: ='HO P&L'!D38 -> 305 | D45: ='HO P&L'!E38 -> 0 | E45: ='HO P&L'!F38 -> 0 | F45: ='HO P&L'!G38 -> 0 | G45: ='Non Staff costs'!C24 -> 0 | H45: ='Non Staff costs'!D24 -> 0 | I45: ='Non Staff costs'!E24 -> 0 | J45: ='Non Staff costs'!F24 -> 0 | K45: ='Non Staff costs'!G24 -> 0 | L45: ='Non Staff costs'!H24 -> 0 | M45: ='Non Staff costs'!I24 -> 0 | N45: ='Non Staff costs'!J24 -> 0 | ... W45: ='Non Staff costs'!S24 -> 0
A46: Travel/ entertainment | B46: 3099.9 | C46: 112.45 | D46: 844.22 | E46: 237.77 | F46: 94.4 | G46: ='Non Staff costs'!C25 -> 0 | H46: ='Non Staff costs'!D25 -> 500 | I46: ='Non Staff costs'!E25 -> 500 | J46: ='Non Staff costs'!F25 -> 500 | K46: ='Non Staff costs'!G25 -> 500 | L46: ='Non Staff costs'!H25 -> 500 | M46: ='Non Staff costs'!I25 -> 500 | N46: ='Non Staff costs'!J25 -> 500 | ... W46: ='Non Staff costs'!S25 -> 500
A47: General expenses | B47: 23.8 | C47: 3005.23 | D47: 1000 | E47: 1000 | F47: 0 | G47: ='Non Staff costs'!C26 -> 500 | H47: ='Non Staff costs'!D26 -> 500 | I47: ='Non Staff costs'!E26 -> 500 | J47: ='Non Staff costs'!F26 -> 500 | K47: ='Non Staff costs'!G26 -> 500 | L47: ='Non Staff costs'!H26 -> 500 | M47: ='Non Staff costs'!I26 -> 500 | N47: ='Non Staff costs'!J26 -> 500 | ... W47: ='Non Staff costs'!S26 -> 500
A48: Total Operating Expenses | B48: =SUM(B38:B47) -> 36334.32 | C48: =SUM(C38:C47) -> 19398.3 | D48: =SUM(D38:D47) -> 29883.39 | E48: =SUM(E38:E47) -> 27282.72 | F48: =SUM(F38:F47) -> 13716.06 | G48: =SUM(G38:G47) -> 2150 | H48: =SUM(H38:H47) -> 3150 | I48: =SUM(I38:I47) -> 3650 | ... W48: =SUM(W38:W47) -> 19150
A50: Operating Profit | B50: =(B34)+(0)-(B48)+(0)-(0) -> -33570.76 | C50: =(C34)+(0)-(C48)+(0)-(0) -> -26981.97 | D50: =(D34)+(0)-(D48)+(0)-(0) -> -32061.3 | E50: =(E34)+(0)-(E48)+(0)-(0) -> -20291.72 | F50: =(F34)+(0)-(F48)+(0)-(0) -> -13601.06 | G50: =(G34)+(0)-(G48)+(0)-(0) -> -4710 | H50: =(H34)+(0)-(H48)+(0)-(0) -> 17482.67 | I50: =(I34)+(0)-(I48)+(0)-(0) -> -15543.33 | ... W50: =(W34)+(0)-(W48)+(0)-(0) -> 8010.0033
A52: Non-operating Expenses
B53: 0 | C53: 0 | D53: 0 | E53: 0 | F53: 0 | G53: 0 | H53: 0 | I53: 0 | J53: 0 | K53: 0 | L53: 0 | M53: 0 | N53: 0 | O53: 0 | P53: 0 | Q53: 0 | R53: 0 | S53: 0 | T53: 0 | U53: 0 | V53: 0 | W53: 0
A54: Depreciation | B54: 0 | C54: 0 | D54: 0 | E54: 0 | F54: 0 | G54: 0 | H54: 0 | I54: 0 | J54: 0 | K54: 0 | L54: 0 | M54: 0 | N54: 0 | O54: 0 | P54: 0 | Q54: 0 | R54: 0 | S54: 0 | T54: 0 | U54: 0 | V54: 0 | W54: 0
A55: Total Non-operating Expenses | B55: =SUM(B53:B54) -> 0 | C55: =SUM(C53:C54) -> 0 | D55: =SUM(D53:D54) -> 0 | E55: =SUM(E53:E54) -> 0 | F55: =SUM(F53:F54) -> 0 | G55: =SUM(G53:G54) -> 0 | H55: =SUM(H53:H54) -> 0 | I55: =SUM(I53:I54) -> 0 | ... W55: =SUM(W53:W54) -> 0
A57: Net Profit | B57: =B50-B55 -> -33570.76 | C57: =C50-C55 -> -26981.97 | D57: =D50-D55 -> -32061.3 | E57: =E50-E55 -> -20291.72 | F57: =F50-F55 -> -13601.06 | G57: =G50-G55 -> -4710 | H57: =H50-H55 -> 17482.67 | I57: =I50-I55 -> -15543.33 | ... W57: =W50-W55 -> 8010.0033

Sheet Revenue summary
C2: 45505 | D2: 45536 | E2: 45566 | F2: 45597 | G2: 45627 | H2: 45658 | I2: 45689 | J2: 45717 | K2: 45748 | L2: 45778 | M2: 45809 | N2: 45839 | O2: 45870 | P2: 45901 | Q2: 45931 | R2: 45962 | S2: 45992
A4: Phase 1 - no capex
A5: Freeholder / MA (Kings Chelsea/ Xenia)
A6: Annual software revenue | C6: 0 | D6: =5202+27324 -> 32526 | E6: 0 | F6: 0 | G6: 0 | H6: 0 | I6: 0 | J6: 0 | K6: 0 | L6: 0 | M6: 0 | N6: 0 | O6: 0 | P6: =D6 -> 32526 | Q6: 0 | R6: 0 | S6: 0
A7: Ad partner revenue | C7: 0 | D7: 0 | E7: 0 | F7: 0 | G7: 0 | H7: 0 | I7: =46000/12 -> 3833.3333 | J7: =46000/12 -> 3833.3333 | K7: =46000/12 -> 3833.3333 | L7: =46000/12 -> 3833.3333 | M7: =46000/12 -> 3833.3333 | N7: =46000/12 -> 3833.3333 | O7: =46000/12 -> 3833.3333 | P7: =46000/12 -> 3833.3333 | ... S7: =46000/12 -> 3833.3333
A11: Phase 2 | B11: Xenia
A12: Units - 7000 | B12: 1 screen/ 75 units | E12: **existing screens
A13: New screens | C13: 0 | D13: 0 | E13: 25 | F13: 17 | G13: 17 | H13: 17 | I13: 17 | J13: 0 | K13: 0 | L13: 0 | M13: 0 | N13: 0 | O13: 0 | P13: 0 | Q13: 0 | R13: 0 | S13: 0
A15: Annual software revenue | B15: =75*1.5*12 -> 1350 | C15: 0 | D15: 0 | E15: 0 | F15: =E13*$B$15 -> 33750 | G15: =F13*$B$15 -> 22950 | H15: =G13*$B$15 -> 22950 | I15: =H13*$B$15 -> 22950 | J15: =I13*$B$15 -> 22950 | K15: 0 | L15: 0 | M15: 0 | N15: 0 | O15: 0 | P15: 0 | Q15: 0 | R15: =F15 -> 33750 | S15: =G15 -> 22950
A16: Ad partner revenue | B16: £50/screen/m | C16: 0 | D16: 0 | E16: 0 | F16: 0 | G16: 0 | H16: =E13*50 -> 1250 | I16: =SUM(E13:F13)*50 -> 2100 | J16: =I16+G13*50 -> 2950 | K16: =J16+H13*50 -> 3800 | L16: =K16+I13*50 -> 4650 | M16: =L16 -> 4650 | N16: =M16 -> 4650 | O16: =N16 -> 4650 | P16: =O16 -> 4650 | Q16: =P16 -> 4650 | R16: =Q16 -> 4650 | S16: =R16 -> 4650
A20: Phase 3 | B20: Xenia
A21: Units - 7000 | B21: 1 screen/ 75 units
A22: New screens | C22: 0 | D22: 0 | E22: 0 | F22: 0 | G22: 0 | H22: 0 | I22: 0 | J22: 0 | K22: 18 | L22: 18 | M22: 19 | N22: 19 | O22: 19 | P22: 0 | Q22: 0 | R22: 0 | S22: 0
A24: Annual software revenue | B24: =75*1.5*12 -> 1350 | C24: 0 | D24: 0 | E24: 0 | F24: 0 | G24: 0 | H24: 0 | I24: 0 | J24: 0 | K24: 0 | L24: =K22*$B$24 -> 24300 | M24: =L22*$B$24 -> 24300 | N24: =M22*$B$24 -> 25650 | O24: =N22*$B$24 -> 25650 | P24: =O22*$B$24 -> 25650 | Q24: 0 | R24: 0 | S24: 0
A25: Ad partner revenue | B25: £50/screen/m | C25: 0 | D25: 0 | E25: 0 | F25: 0 | G25: 0 | H25: 0 | I25: 0 | J25: 0 | K25: 0 | L25: 0 | M25: 0 | N25: =K22*50 -> 900 | O25: =N25+L22*50 -> 1800 | P25: =O25+M22*50 -> 2750 | Q25: =P25+N22*50 -> 3700 | R25: =Q25+O22*50 -> 4650 | S25: =R25 -> 4650
A29: Phase 4 | B29: Xenia
A30: Units - 7000 | B30: 1 screen/ 75 units
A31: New screens | C31: 0 | D31: 0 | E31: 0 | F31: 0 | G31: 0 | H31: 0 | I31: 0 | J31: 0 | K31: 0 | L31: 0 | M31: 18 | N31: 18 | O31: 19 | P31: 19 | Q31: 19 | R31: 0 | S31: 0
A33: Annual software revenue | B33: =75*1.5*12 -> 1350 | C33: 0 | D33: 0 | E33: 0 | F33: 0 | G33: 0 | H33: 0 | I33: 0 | J33: 0 | K33: 0 | L33: 0 | M33: 0 | N33: =M31*$B$33 -> 24300 | O33: =N31*$B$33 -> 24300 | P33: =O31*$B$33 -> 25650 | Q33: =P31*$B$33 -> 25650 | R33: =Q31*$B$33 -> 25650 | S33: 0
A34: Ad partner revenue | B34: £50/screen/m | C34: 0 | D34: 0 | E34: 0 | F34: 0 | G34: 0 | H34: 0 | I34: 0 | J34: 0 | K34: 0 | L34: 0 | M34: 0 | N34: 0 | O34: 0 | P34: 0 | Q34: 0 | R34: 0 | S34: 0
A38: JTRE / Rhodium
A39: New screens | C39: 0 | D39: 0 | E39: 4 | F39: 0 | G39: 0 | H39: 0 | I39: 0 | J39: 0 | K39: 0 | L39: 0 | M39: 0 | N39: 0 | O39: 0 | P39: 0 | Q39: 0 | R39: 0 | S39: 0
A41: Annual software revenue | C41: 0 | D41: 0 | E41: 0 | F41: 10056 | G41: 0 | H41: 0 | I41: 0 | J41: 0 | K41: 0 | L41: 0 | M41: 0 | N41: 0 | O41: 0 | P41: 0 | Q41: 0 | R41: =F41 -> 10056 | S41: 0
A42: Ad partner revenue | C42: 0 | D42: 0 | E42: 0 | F42: 0 | G42: 0 | H42: 0 | I42: =15000/12 -> 1250 | J42: =I42 -> 1250 | K42: =J42 -> 1250 | L42: =K42 -> 1250 | M42: =L42 -> 1250 | N42: =M42 -> 1250 | O42: =N42 -> 1250 | P42: =O42 -> 1250 | Q42: =P42 -> 1250 | ... S42: =R42 -> 1250
A46: Existing screens revenue | B46: 20 screens
A48: Annual software revenue | B48: 1000 | C48: 0 | D48: 0 | E48: 0 | F48: 0 | G48: =B48*5 -> 5000 | H48: =G48 -> 5000 | I48: =H48 -> 5000 | J48: =I48 -> 5000 | K48: 0 | L48: 0 | M48: 0 | N48: 0 | O48: 0 | P48: 0 | Q48: 0 | R48: 0 | S48: =G48 -> 5000
A49: Ad partner revenue | B49: 50 | C49: 0 | D49: 0 | E49: 0 | F49: 0 | G49: 0 | H49: 0 | I49: 0 | J49: =B49*20 -> 1000 | K49: =J49 -> 1000 | L49: =K49 -> 1000 | M49: =L49 -> 1000 | N49: =M49 -> 1000 | O49: =N49 -> 1000 | P49: =O49 -> 1000 | Q49: =P49 -> 1000 | R49: =Q49 -> 1000 | S49: =R49 -> 1000
A55: Capex./ screen
A57: Cost of Screen | C57: 600 | D57: 600 | E57: 600 | F57: 600 | G57: 600 | H57: 600 | I57: 600 | J57: 600 | K57: 600 | L57: 600 | M57: 600 | N57: 600 | O57: 600 | P57: 600 | Q57: 600 | R57: 600 | S57: 600
A58: Screen Set up and Installation | C58: 500 | D58: 500 | E58: 500 | F58: 500 | G58: 500 | H58: 500 | I58: 500 | J58: 500 | K58: 500 | L58: 500 | M58: 500 | N58: 500 | O58: 500 | P58: 500 | Q58: 500 | R58: 500 | S58: 500
A60: New screens | C60: =C13+C22+C31+C39 -> 0 | D60: =D13+D22+D31+D39 -> 0 | E60: =E22+E31+E39 -> 4 | F60: =F13+F22+F31+F39 -> 17 | G60: =G13+G22+G31+G39 -> 17 | H60: =H13+H22+H31+H39 -> 17 | I60: =I13+I22+I31+I39 -> 17 | J60: =J13+J22+J31+J39 -> 0 | K60: =K13+K22+K31+K39 -> 18 | L60: =L13+L22+L31+L39 -> 18 | M60: =M13+M22+M31+M39 -> 37 | ... S60: =S13+S22+S31+S39 -> 0
C63: =C6+C15+C41 -> 0 | D63: =D6+D15+D41+D24+D33+D48 -> 32526 | E63: =E6+E15+E41+E24+E33+E48 -> 0 | F63: =F6+F15+F41+F24+F33+F48 -> 43806 | G63: =G6+G15+G41+G24+G33+G48 -> 27950 | H63: =H6+H15+H41+H24+H33+H48 -> 27950 | I63: =I6+I15+I41+I24+I33+I48 -> 27950 | J63: =J6+J15+J41+J24+J33+J48 -> 27950 | K63: =K6+K15+K41+K24+K33+K48 -> 0 | ... S63: =S6+S15+S41+S24+S33+S48 -> 27950
C64: =C7+C16+C42+C25+C34+C49 -> 0 | D64: =D7+D16+D42+D25+D34+D49 -> 0 | E64: =E7+E16+E42+E25+E34+E49 -> 0 | F64: =F7+F16+F42+F25+F34+F49 -> 0 | G64: =G7+G16+G42+G25+G34+G49 -> 0 | H64: =H7+H16+H42+H25+H34+H49 -> 1250 | I64: =I7+I16+I42+I25+I34+I49 -> 7183.3333 | J64: =J7+J16+J42+J25+J34+J49 -> 9033.3333 | ... S64: =S7+S16+S42+S25+S34+S49 -> 15383.333

Sheet Non Staff costs
B1: Cost per screen | C1: 45505 | D1: 45536 | E1: 45566 | F1: 45597 | G1: 45627 | H1: 45658 | I1: 45689 | J1: 45717 | K1: 45748 | L1: 45778 | M1: 45809 | N1: 45839 | O1: 45870 | P1: 45901 | Q1: 45931 | R1: 45962 | S1: 45992
A3: New screens per month | C3: ='Consolidated P&L'!G5 -> 0 | D3: ='Consolidated P&L'!H5 -> 0 | E3: ='Consolidated P&L'!I5 -> 4 | F3: ='Consolidated P&L'!J5 -> 17 | G3: ='Consolidated P&L'!K5 -> 17 | H3: ='Consolidated P&L'!L5 -> 17 | I3: ='Consolidated P&L'!M5 -> 17 | J3: ='Consolidated P&L'!N5 -> 0 | ... S3: ='Consolidated P&L'!W5 -> 0
A4: Total screens | C4: ='Consolidated P&L'!G6 -> 210 | D4: ='Consolidated P&L'!H6 -> 210 | E4: ='Consolidated P&L'!I6 -> 214 | F4: ='Consolidated P&L'!J6 -> 231 | G4: ='Consolidated P&L'!K6 -> 248 | H4: ='Consolidated P&L'!L6 -> 265 | I4: ='Consolidated P&L'!M6 -> 282 | J4: ='Consolidated P&L'!N6 -> 282 | ... S4: ='Consolidated P&L'!W6 -> 468
A6: LDSK | B6: 0 | C6: 2560 | D6: 2560 | E6: 2560 | F6: 2560 | G6: 0 | H6: 0 | I6: 0 | J6: 0 | K6: 0 | L6: 0 | M6: 0 | N6: 0 | O6: =O3*$B$6 -> 0 | P6: =P3*$B$6 -> 0 | Q6: =Q3*$B$6 -> 0 | R6: =R3*$B$6 -> 0 | S6: =S3*$B$6 -> 0
A7: Screens - support fee | B7: 15 | C7: 0 | D7: 0 | E7: 0 | F7: 0 | G7: =5*B7 -> 75 | H7: =G7+5*$B$7 -> 150 | I7: =H7+5*$B$7 -> 225 | J7: =I7+5*$B$7 -> 300 | K7: =J7 -> 300 | L7: =K7 -> 300 | M7: =L7 -> 300 | N7: =M7 -> 300 | O7: =N7 -> 300 | P7: =O7 -> 300 | Q7: =P7 -> 300 | R7: =Q7 -> 300 | S7: =R7 -> 300
A8: Direct costs 3 | B8: 0 | C8: 0 | D8: 0 | E8: 0 | F8: 0 | G8: 0 | H8: 0 | I8: 0 | J8: 0 | K8: 0 | L8: 0 | M8: 0 | N8: 0 | O8: =$B$8*O3 -> 0 | P8: =$B$8*P3 -> 0 | Q8: =$B$8*Q3 -> 0 | R8: =$B$8*R3 -> 0 | S8: =$B$8*S3 -> 0
A9: Direct costs 4 | B9: 0 | C9: 0 | D9: 0 | E9: 0 | F9: 0 | G9: 0 | H9: 0 | I9: 0 | J9: 0 | K9: 0 | L9: 0 | M9: 0 | N9: 0 | O9: =$B$9*O3 -> 0 | P9: =$B$9*P3 -> 0 | Q9: =$B$9*Q3 -> 0 | R9: =$B$9*R3 -> 0 | S9: =$B$9*S3 -> 0
A10: Direct costs 5 | B10: 0 | C10: 0 | D10: 0 | E10: 0 | F10: 0 | G10: 0 | H10: 0 | I10: 0 | J10: 0 | K10: 0 | L10: 0 | M10: 0 | N10: 0 | O10: =$B$10*O4 -> 0 | P10: =$B$10*P4 -> 0 | Q10: =$B$10*Q4 -> 0 | R10: =$B$10*R4 -> 0 | S10: =$B$10*S4 -> 0
A11: Direct costs 6 | B11: 0 | C11: 0 | D11: 0 | E11: 0 | F11: 0 | G11: 0 | H11: 0 | I11: 0 | J11: 0 | K11: 0 | L11: 0 | M11: 0 | N11: 0 | O11: =M4*$B$11 -> 0 | P11: =N4*$B$11 -> 0 | Q11: =O4*$B$11 -> 0 | R11: =P4*$B$11 -> 0 | S11: =Q4*$B$11 -> 0
A13: Total direct costs | C13: =SUM(C6:C11) -> 2560 | D13: =SUM(D6:D11) -> 2560 | E13: =SUM(E6:E11) -> 2560 | F13: =SUM(F6:F11) -> 2560 | G13: =SUM(G6:G11) -> 75 | H13: =SUM(H6:H11) -> 150 | I13: =SUM(I6:I11) -> 225 | J13: =SUM(J6:J11) -> 300 | ... S13: =SUM(S6:S11) -> 300
A15: Overheads
A17: Consulting | C17: 0 | D17: 0 | E17: 0 | F17: 0 | G17: 0 | H17: 0 | I17: 0 | J17: 0 | K17: 0 | L17: 0 | M17: 0 | N17: 0 | O17: 0 | P17: 0 | Q17: 0 | R17: 0 | S17: 0
A18: Marketing/ Advertising | C18: 0 | D18: 0 | E18: 500 | F18: 500 | G18: 500 | H18: 500 | I18: 500 | J18: 500 | K18: 500 | L18: 500 | M18: 500 | N18: 500 | O18: 500 | P18: 500 | Q18: 500 | R18: 500 | S18: 500
A19: Sundries/expenses/legals | C19: 0 | D19: 0 | E19: 0 | F19: 0 | G19: 0 | H19: 0 | I19: 0 | J19: 0 | K19: 0 | L19: 0 | M19: 0 | N19: 0 | O19: 0 | P19: 0 | Q19: 0 | R19: 0 | S19: 0
A20: Software Development costs | C20: 0 | D20: 0 | E20: 0 | F20: 5000 | G20: =F20 -> 5000 | H20: =G20 -> 5000 | I20: =H20 -> 5000 | J20: =I20 -> 5000 | K20: =J20 -> 5000 | L20: =K20 -> 5000 | M20: =L20 -> 5000 | N20: =M20 -> 5000 | ... S20: =R20 -> 5000
A21: Bookkeeping & Accountancy fees | C21: 0 | D21: 500 | E21: 500 | F21: 500 | G21: 500 | H21: 500 | I21: 1000 | J21: 1000 | K21: 1000 | L21: 1000 | M21: 1000 | N21: 1000 | O21: 1000 | P21: 1000 | Q21: 1000 | R21: 1000 | S21: 1000
A22: Office costs/ rent | C22: 1500 | D22: 1500 | E22: 1500 | F22: 1500 | G22: 1500 | H22: 1500 | I22: 1500 | J22: 1500 | K22: 1500 | L22: 1500 | M22: 1500 | N22: 1500 | O22: 1500 | P22: 1500 | Q22: 1500 | R22: 1500 | S22: 1500
A23: Subscriptions | C23: 150 | D23: 150 | E23: 150 | F23: 150 | G23: 150 | H23: 150 | I23: 150 | J23: 150 | K23: 150 | L23: 150 | M23: 150 | N23: 150 | O23: 150 | P23: 150 | Q23: 150 | R23: 150 | S23: 150
A24: Postage, Freight & Courier | C24: 0 | D24: 0 | E24: 0 | F24: 0 | G24: 0 | H24: 0 | I24: 0 | J24: 0 | K24: 0 | L24: 0 | M24: 0 | N24: 0 | O24: 0 | P24: 0 | Q24: 0 | R24: 0 | S24: 0
A25: Travel/ entertainment | C25: 0 | D25: 500 | E25: 500 | F25: 500 | G25: 500 | H25: 500 | I25: 500 | J25: 500 | K25: 500 | L25: 500 | M25: 500 | N25: 500 | O25: 500 | P25: 500 | Q25: 500 | R25: 500 | S25: 500
A26: General expenses | C26: 500 | D26: 500 | E26: 500 | F26: 500 | G26: 500 | H26: 500 | I26: 500 | J26: 500 | K26: 500 | L26: 500 | M26: 500 | N26: 500 | O26: 500 | P26: 500 | Q26: 500 | R26: 500 | S26: 500
A28: Total | B28: =SUM(B17:B26) -> 0 | C28: =SUM(C17:C26) -> 2150 | D28: =SUM(D17:D26) -> 3150 | E28: =SUM(E17:E26) -> 3650 | F28: =SUM(F17:F26) -> 8650 | G28: =SUM(G17:G26) -> 8650 | H28: =SUM(H17:H26) -> 8650 | I28: =SUM(I17:I26) -> 9150 | ... S28: =SUM(S17:S26) -> 9150

Sheet Staff costs
A1: Name | B1: Title | C1: Department | D1: Annual salary | E1: Gross Pay | F1: Employer NI | G1: Pension | H1: Total | J1: 45528 | K1: 45559 | L1: 45589 | M1: 45620 | N1: 45650 | O1: 45682 | P1: 45713 | Q1: 45741 | R1: 45772 | S1: 45802 | T1: 45833 | U1: 45863 | V1: 45894 | W1: 45925 | X1: 45955 | Y1: 45986 | Z1: 46016
A2: Stephen | C2: Contractor | D2: 72000 | E2: =ROUND(D2/12,2) -> 6000 | F2: 0 | G2: 0 | H2: =(E2+F2+G2) -> 6000 | J2: 0 | K2: =$H$2/2 -> 3000 | L2: =$H$2/2 -> 3000 | M2: =$H$2/2 -> 3000 | N2: =$H$2 -> 6000 | O2: =$H$2 -> 6000 | P2: =$H$2 -> 6000 | Q2: =$H$2 -> 6000 | R2: =$H$2 -> 6000 | S2: =$H$2 -> 6000 | T2: =$H$2 -> 6000 | U2: =$H$2 -> 6000 | ... Z2: =$H$2 -> 6000
A3: Dave | C3: Contractor | D3: 76000 | E3: =ROUND(D3/12,2) -> 6333.33 | F3: 0 | G3: 0 | H3: =(E3+F3+G3) -> 6333.33 | J3: 0 | K3: =$H3 -> 6333.33 | L3: =$H3 -> 6333.33 | M3: =$H3 -> 6333.33 | N3: =$H3 -> 6333.33 | O3: =$H3 -> 6333.33 | P3: =$H3 -> 6333.33 | Q3: =$H3 -> 6333.33 | R3: =$H3 -> 6333.33 | ... Z3: =$H3 -> 6333.33
A4: TBC | C4: Employee | D4: 36000 | E4: =ROUND(D4/12,2) -> 3000 | F4: =ROUND(D4*15%/12,2) -> 450 | G4: =ROUND((E4)*3%,2) -> 90 | H4: =(E4+F4+G4) -> 3540 | J4: 0 | K4: 0 | L4: 0 | M4: =H4 -> 3540 | N4: =M4 -> 3540 | O4: =N4 -> 3540 | P4: =O4 -> 3540 | Q4: =P4 -> 3540 | R4: =Q4 -> 3540 | S4: =R4 -> 3540 | T4: =S4 -> 3540 | U4: =T4 -> 3540 | ... Z4: =Y4 -> 3540
A5: TBC | E5: =ROUND(D5/12,2) -> 0 | F5: =ROUND(D5*15%/12,2) -> 0 | G5: =ROUND((E5)*3%,2) -> 0 | H5: =(E5+F5+G5) -> 0 | J5: 0 | K5: =$H5 -> 0 | L5: =$H5 -> 0 | M5: =$H5 -> 0 | N5: =$H5 -> 0 | O5: =$H5 -> 0 | P5: =$H5 -> 0 | Q5: =$H5 -> 0 | R5: =$H5 -> 0 | ... Z5: =$H5 -> 0
A6: TBC | E6: =ROUND(D6/12,2) -> 0 | F6: =ROUND(D6*15%/12,2) -> 0 | G6: =ROUND((E6)*3%,2) -> 0 | H6: =(E6+F6+G6) -> 0 | J6: 0 | K6: =$H6 -> 0 | L6: =$H6 -> 0 | M6: =$H6 -> 0 | N6: =$H6 -> 0 | O6: =$H6 -> 0 | P6: =$H6 -> 0 | Q6: =$H6 -> 0 | R6: =$H6 -> 0 | ... Z6: =$H6 -> 0
A7: Owen | C7: Director | D7: 0 | E7: =ROUND(D7/12,2) -> 0 | F7: =ROUND(D7*15%/12,2) -> 0 | G7: =ROUND((E7)*3%,2) -> 0 | H7: =(E7+F7+G7) -> 0 | J7: =$H7 -> 0 | K7: =$H7 -> 0 | L7: 0 | M7: 0 | N7: 0 | O7: 0 | P7: 0 | Q7: 0 | R7: 0 | S7: 0 | T7: 0 | U7: 0 | V7: 5000 | W7: 5000 | X7: 5000 | Y7: 5000 | Z7: 5000
A8: Tony | C8: Director | D8: 0 | E8: =ROUND(D8/12,2) -> 0 | F8: =ROUND(D8*15%/12,2) -> 0 | G8: =ROUND((E8)*3%,2) -> 0 | H8: =(E8+F8+G8) -> 0 | J8: =$H8 -> 0 | K8: =$H8 -> 0 | L8: 0 | M8: 0 | N8: 0 | O8: 0 | P8: 0 | Q8: 0 | R8: 0 | S8: 0 | T8: 0 | U8: 0 | V8: 5000 | W8: 5000 | X8: 5000 | Y8: 5000 | Z8: 5000
I10: Total employees | J10: =SUM(J2:J8)-J2-J7-J8 -> 0 | K10: 0 | L10: 0 | M10: =SUMIF($C$2:$C$8,$C$20,$H$2:$H$8) -> 3540 | N10: =SUMIF($C$2:$C$8,$C$20,$H$2:$H$8) -> 3540 | O10: =SUMIF($C$2:$C$8,$C$20,$H$2:$H$8) -> 3540 | P10: =SUMIF($C$2:$C$8,$C$20,$H$2:$H$8) -> 3540 | Q10: =SUMIF($C$2:$C$8,$C$20,$H$2:$H$8) -> 3540 | R10: =SUMIF($C$2:$C$8,$C$20,$H$2:$H$8) -> 3540 | S10: =SUMIF($C$2:$C$8,$C$20,$H$2:$H$8) -> 3540 | T10: =SUMIF($C$2:$C$8,$C$20,$H$2:$H$8) -> 3540 | ... Z10: =SUMIF($C$2:$C$8,$C$20,$H$2:$H$8) -> 3540
I12: Total contractors | J12: =SUM(J2:J3) -> 0 | K12: =SUM(K2:K3) -> 9333.33 | L12: =SUM(L2:L3) -> 9333.33 | M12: =SUM(M2:M3) -> 9333.33 | N12: =SUM(N2:N3) -> 12333.33 | O12: =SUM(O2:O3) -> 12333.33 | P12: =SUM(P2:P3) -> 12333.33 | Q12: =SUM(Q2:Q3) -> 12333.33 | ... Z12: =SUM(Z2:Z3) -> 12333.33
K14: =SUM(K2:K8)-SUM(K10:K12) -> 0 | L14: =SUM(L2:L6)-SUM(L10:L12) -> 0 | M14: =SUM(M2:M6)-SUM(M10:M12) -> 0 | N14: =SUM(N2:N6)-SUM(N10:N12) -> 0 | O14: =SUM(O2:O6)-SUM(O10:O12) -> 0 | P14: =SUM(P2:P6)-SUM(P10:P12) -> 0 | Q14: =SUM(Q2:Q6)-SUM(Q10:Q12) -> 0 | R14: =SUM(R2:R6)-SUM(R10:R12) -> 0 | S14: =SUM(S2:S6)-SUM(S10:S12) -> 0 | ... Z14: =SUM(Z2:Z6)-SUM(Z10:Z12) -> 0
C20: Employee

Sheet Working Capital
A2: VAT | B2: 45352 | C2: 45383 | D2: 45413 | E2: 45444 | F2: 45474 | G2: 45505 | H2: 45536 | I2: 45566 | J2: 45597 | K2: 45627 | L2: 45658 | M2: 45689 | N2: 45717 | O2: 45748 | P2: 45778 | Q2: 45809 | R2: 45839 | S2: 45870 | T2: 45901 | U2: 45931 | V2: 45962 | W2: 45992
A3: O/bal | B3: ='Balance Sheet'!B30 -> -24342.65 | C3: ='Balance Sheet'!C30 -> -27173.05 | D3: ='Balance Sheet'!D30 -> -5060.29 | E3: ='Balance Sheet'!E30 -> -5328.09 | F3: ='Balance Sheet'!F30 -> -4387.09 | G3: =F7 -> -4387.09 | H3: =G7 -> -9329.09 | I3: =H7 -> -5832.56 | J3: =I7 -> -8941.23 | K3: =J7 -> 835.86 | L3: =K7 -> 1506.19 | M3: =L7 -> 2411.52 | N3: =M7 -> 2882.33 | ... W3: =V7 -> 10855.2
A4: VAT On Sales | G4: =ROUND('Consolidated P&L'!G16*0.2,2) -> 0 | H4: =ROUND('Consolidated P&L'!H16*0.2,2) -> 6505.2 | I4: =ROUND('Consolidated P&L'!I16*0.2,2) -> 0 | J4: =ROUND('Consolidated P&L'!J16*0.2,2) -> 8761.2 | K4: =ROUND('Consolidated P&L'!K16*0.2,2) -> 5590 | L4: =ROUND('Consolidated P&L'!L16*0.2,2) -> 5840 | M4: =ROUND('Consolidated P&L'!M16*0.2,2) -> 7026.67 | N4: =ROUND('Consolidated P&L'!N16*0.2,2) -> 7396.67 | ... W4: =ROUND('Consolidated P&L'!W16*0.2,2) -> 8666.67
A5: VAT on Purchases | G5: =ROUND(-(SUM('Consolidated P&L'!G19:G25)+SUM('Consolidated P&L'!G38:G47)+'Consolidated P&L'!G27+'Consolidated P&L'!G28)*20%,2) -> -942 | H5: =ROUND(-(SUM('Consolidated P&L'!H19:H25)+SUM('Consolidated P&L'!H38:H47)+'Consolidated P&L'!H27+'Consolidated P&L'!H28+'Consolidated P&L'!H29)*20%,2) -> -3008.67 | I5: =ROUND(-(SUM('Consolidated P&L'!I19:I25)+SUM('Consolidated P&L'!I38:I47)+'Consolidated P&L'!I27+'Consolidated P&L'!I28+'Consolidated P&L'!I29)*20%,2) -> -3108.67 | J5: =ROUND(-(SUM('Consolidated P&L'!J19:J25)+SUM('Consolidated P&L'!J38:J47)+'Consolidated P&L'!J27+'Consolidated P&L'!J28+'Consolidated P&L'!J29)*20%,2) -> -4816.67 | K5: =ROUND(-(SUM('Consolidated P&L'!K19:K25)+SUM('Consolidated P&L'!K38:K47)+'Consolidated P&L'!K27+'Consolidated P&L'!K28+'Consolidated P&L'!K29)*20%,2) -> -4919.67 | L5: =ROUND(-(SUM('Consolidated P&L'!L19:L25)+SUM('Consolidated P&L'!L38:L47)+'Consolidated P&L'!L27+'Consolidated P&L'!L28+'Consolidated P&L'!L29)*20%,2) -> -4934.67 | M5: =ROUND(-(SUM('Consolidated P&L'!M19:M25)+SUM('Consolidated P&L'!M38:M47)+'Consolidated P&L'!M27+'Consolidated P&L'!M28+'Consolidated P&L'!M29)*20%,2) -> -5049.67 | N5: =ROUND(-(SUM('Consolidated P&L'!N19:N25)+SUM('Consolidated P&L'!N38:N47)+'Consolidated P&L'!N27+'Consolidated P&L'!N28+'Consolidated P&L'!N29)*20%,2) -> -5064.67 | O5: =ROUND(-(SUM('Consolidated P&L'!O19:O25)+SUM('Consolidated P&L'!O38:O47)+'Consolidated P&L'!O27+'Consolidated P&L'!O28+'Consolidated P&L'!O29)*20%,2) -> -5064.67 | ... W5: =ROUND(-(SUM('Consolidated P&L'!W19:W25)+SUM('Consolidated P&L'!W38:W47)+'Consolidated P&L'!W27+'Consolidated P&L'!W28+'Consolidated P&L'!W29)*20%,2) -> -7064.67
A6: VAT Payment (Jun; Sept; Dec; Mar) | G6: =-4000 -> -4000 | J6: =-H7 -> 5832.56 | M6: =-K7 -> -1506.19 | P6: =-N7 -> -5214.33 | S6: =-Q7 -> -796 | V6: =-T7 -> -25081.2
A7: C/bal | B7: =SUM(B3:B6) -> -24342.65 | C7: =SUM(C3:C6) -> -27173.05 | D7: =SUM(D3:D6) -> -5060.29 | E7: =SUM(E3:E6) -> -5328.09 | F7: =SUM(F3:F6) -> -4387.09 | G7: =SUM(G3:G6) -> -9329.09 | H7: =SUM(H3:H6) -> -5832.56 | I7: =SUM(I3:I6) -> -8941.23 | ... W7: =SUM(W3:W6) -> 12457.2
A11: Trade Debtors | B11: 44986 | C11: 45017 | D11: 45047 | E11: 45078 | F11: 45108 | G11: 45139 | H11: 45170 | I11: 45200 | J11: 45231 | K11: 45261 | L11: 45292 | M11: 45323 | N11: 45324 | O11: 45325 | P11: 45326 | Q11: 45327 | R11: 45328 | S11: 45329 | T11: 45330 | U11: 45331 | V11: 45332 | W11: 45333
A12: O/bal | B12: ='Balance Sheet'!B11 -> 63292 | C12: ='Balance Sheet'!C11 -> 85462 | D12: ='Balance Sheet'!D11 -> 107632 | E12: ='Balance Sheet'!E11 -> 129142 | F12: ='Balance Sheet'!F11 -> 21592 | G12: =F16 -> 21592 | H12: =G16 -> 21592 | I12: =H16 -> 50623.2 | J12: =I16 -> 6592 | K12: =J16 -> 59159.2 | L12: =K16 -> 40132 | M12: =L16 -> 41632 | N12: =M16 -> 48752 | ... W12: =V16 -> 108399.2
A13: Sales | G13: =ROUND('Consolidated P&L'!G16*1.2,2) -> 0 | H13: =ROUND('Consolidated P&L'!H16*1.2,2) -> 39031.2 | I13: =ROUND('Consolidated P&L'!I16*1.2,2) -> 0 | J13: =ROUND('Consolidated P&L'!J16*1.2,2) -> 52567.2 | K13: =ROUND('Consolidated P&L'!K16*1.2,2) -> 33540 | L13: =ROUND('Consolidated P&L'!L16*1.2,2) -> 35040 | M13: =ROUND('Consolidated P&L'!M16*1.2,2) -> 42160 | N13: =ROUND('Consolidated P&L'!N16*1.2,2) -> 44380 | ... W13: =ROUND('Consolidated P&L'!W16*1.2,2) -> 52000
A14: Receipt | G14: =-F13 -> 0 | H14: =-G13 -> 0 | I14: =-H13 -> -39031.2 | J14: =-I13 -> 0 | K14: =-J13 -> -52567.2 | L14: =-K13 -> -33540 | M14: =-L13 -> -35040 | N14: =-M13 -> -42160 | ... W14: =-V13 -> -101807.2
A15: Aged Receivable | G15: 0 | H15: -10000 | I15: -5000
A16: C/bal | B16: =SUM(B12:B15) -> 63292 | C16: =SUM(C12:C15) -> 85462 | D16: =SUM(D12:D15) -> 107632 | E16: =SUM(E12:E15) -> 129142 | F16: =SUM(F12:F15) -> 21592 | G16: =SUM(G12:G15) -> 21592 | H16: =SUM(H12:H15) -> 50623.2 | I16: =SUM(I12:I15) -> 6592 | ... W16: =SUM(W12:W15) -> 58592
A19: Trade Creditors | B19: 44986 | C19: 45017 | D19: 45047 | E19: 45078 | F19: 45108 | G19: 45139 | H19: 45170 | I19: 45200 | J19: 45231 | K19: 45261 | L19: 45292 | M19: 45323 | N19: 45324 | O19: 45325 | P19: 45326 | Q19: 45327 | R19: 45328 | S19: 45329 | T19: 45330 | U19: 45331 | V19: 45332 | W19: 45333
A20: O/bal | B20: ='Balance Sheet'!B27 -> 78309.98 | C20: ='Balance Sheet'!C27 -> 115566.38 | D20: ='Balance Sheet'!D27 -> 124836.9 | E20: ='Balance Sheet'!E27 -> 158897.03 | F20: ='Balance Sheet'!F27 -> 83451.5 | G20: =F24 -> 83451.5 | H20: =G24 -> 89103.5 | I20: =H24 -> 101503.5 | J20: =I24 -> 93603.5 | K20: =J24 -> 99881.5 | L20: =K24 -> 99499.5 | M20: =L24 -> 98589.5 | N20: =M24 -> 98279.5 | ... W20: =V24 -> 101369.5
A21: Purchases | G21: =ROUND((SUM('Consolidated P&L'!G19:G24)+'Consolidated P&L'!G30+SUM('Consolidated P&L'!G38:G47))*1.2,2) -> 5652 | H21: =ROUND((SUM('Consolidated P&L'!H19:H24)+'Consolidated P&L'!H30+SUM('Consolidated P&L'!H38:H47))*1.2,2) -> 18052 | I21: =ROUND((SUM('Consolidated P&L'!I19:I24)+'Consolidated P&L'!I30+SUM('Consolidated P&L'!I38:I47))*1.2,2) -> 18652 | J21: =ROUND((SUM('Consolidated P&L'!J19:J24)+'Consolidated P&L'!J30+SUM('Consolidated P&L'!J38:J47))*1.2,2) -> 28900 | K21: =ROUND((SUM('Consolidated P&L'!K19:K24)+'Consolidated P&L'!K30+SUM('Consolidated P&L'!K38:K47))*1.2,2) -> 29518 | L21: =ROUND((SUM('Consolidated P&L'!L19:L24)+'Consolidated P&L'!L30+SUM('Consolidated P&L'!L38:L47))*1.2,2) -> 29608 | M21: =ROUND((SUM('Consolidated P&L'!M19:M24)+'Consolidated P&L'!M30+SUM('Consolidated P&L'!M38:M47))*1.2,2) -> 30298 | N21: =ROUND((SUM('Consolidated P&L'!N19:N24)+'Consolidated P&L'!N30+SUM('Consolidated P&L'!N38:N47))*1.2,2) -> 30388 | ... W21: =ROUND((SUM('Consolidated P&L'!W19:W24)+'Consolidated P&L'!W30+SUM('Consolidated P&L'!W38:W47))*1.2,2) -> 42388
A22: Payment | G22: 0 | H22: =-G21 -> -5652 | I22: =-H21 -> -18052 | J22: =-I21 -> -18652 | K22: =-J21 -> -28900 | L22: =-K21 -> -29518 | M22: =-L21 -> -29608 | N22: =-M21 -> -30298 | O22: =-N21 -> -30388 | ... W22: =-V21 -> -42388
I23: -8500 | J23: =-1000-2970 -> -3970 | K23: -1000 | L23: -1000 | M23: -1000 | N23: -1000 | O23: -1000 | P23: -1000 | Q23: -1000 | R23: -1000 | S23: -1000 | T23: -1000 | U23: -1000 | V23: -1000 | W23: -1000
A24: C/bal | B24: =SUM(B20:B23) -> 78309.98 | C24: =SUM(C20:C23) -> 115566.38 | D24: =SUM(D20:D23) -> 124836.9 | E24: =SUM(E20:E23) -> 158897.03 | F24: =SUM(F20:F23) -> 83451.5 | G24: =SUM(G20:G23) -> 89103.5 | H24: =SUM(H20:H23) -> 101503.5 | I24: =SUM(I20:I23) -> 93603.5 | ... W24: =SUM(W20:W23) -> 100369.5
A28: PPE
A30: Opening | B30: 0 | C30: =B34 -> 0 | D30: =C34 -> 0 | E30: =D34 -> 0 | F30: =E34 -> 0 | G30: =F34 -> 0 | H30: =G34 -> 0 | I30: =H34 -> 0 | J30: =I34 -> 16900 | ... W30: =V34 -> 296300
A31: Additions | B31: 0 | C31: 0 | D31: 0 | E31: 0 | F31: 0 | G31: =600*'Eris P&L'!H6 -> 0 | H31: =600*'Eris P&L'!I6 -> 0 | I31: ='Revenue summary'!E60*SUM('Revenue summary'!E57:E58)+'Revenue summary'!E13*'Revenue summary'!E58 -> 16900 | J31: ='Revenue summary'!F60*SUM('Revenue summary'!F57:F58) -> 18700 | K31: ='Revenue summary'!G60*SUM('Revenue summary'!G57:G58) -> 18700 | L31: ='Revenue summary'!H60*SUM('Revenue summary'!H57:H58) -> 18700 | M31: ='Revenue summary'!I60*SUM('Revenue summary'!I57:I58) -> 18700 | N31: ='Revenue summary'!J60*SUM('Revenue summary'!J57:J58) -> 0 | O31: ='Revenue summary'!K60*SUM('Revenue summary'!K57:K58) -> 19800 | P31: ='Revenue summary'!L60*SUM('Revenue summary'!L57:L58) -> 19800 | Q31: ='Revenue summary'!M60*SUM('Revenue summary'!M57:M58) -> 40700 | R31: ='Consolidated P&L'!R5*SUM('Revenue summary'!N57:N58) -> 40700 | S31: ='Consolidated P&L'!S5*SUM('Revenue summary'!O57:O58) -> 41800 | T31: ='Consolidated P&L'!T5*SUM('Revenue summary'!P57:P58) -> 20900 | U31: ='Consolidated P&L'!U5*SUM('Revenue summary'!Q57:Q58) -> 20900 | V31: ='Consolidated P&L'!V5*SUM('Revenue summary'!R57:R58) -> 0 | W31: ='Consolidated P&L'!W5*SUM('Revenue summary'!S57:S58) -> 0
A32: Depreciation | B32: 0 | C32: 0 | D32: 0 | E32: 0 | F32: 0 | G32: 0 | H32: 0 | I32: 0 | J32: 0 | K32: 0 | L32: 0 | M32: 0 | N32: 0 | O32: 0 | P32: 0 | Q32: 0 | R32: 0 | S32: 0 | T32: 0 | U32: 0 | V32: 0 | W32: 0
A34: Closing | B34: =SUM(B30:B32) -> 0 | C34: =SUM(C30:C32) -> 0 | D34: =SUM(D30:D32) -> 0 | E34: =SUM(E30:E32) -> 0 | F34: =SUM(F30:F32) -> 0 | G34: =SUM(G30:G32) -> 0 | H34: =SUM(H30:H32) -> 0 | I34: =SUM(I30:I32) -> 16900 | ... W34: =SUM(W30:W32) -> 296300
A36: Bank
A37: O/bal | B37: ='Balance Sheet'!B7 -> 31202.64 | C37: ='Balance Sheet'!C7 -> 16132.54 | D37: ='Balance Sheet'!D7 -> 4816.48 | E37: ='Balance Sheet'!E7 -> 512.86 | F37: ='Balance Sheet'!F7 -> 8419.76 | G37: =F41 -> 2419.76 | H37: =G41 -> -1580.24 | I37: =H41 -> 2767.76 | J37: =I41 -> 3346.96 | K37: =J41 -> -32142.48 | L37: =K41 -> -28175.28 | M37: =L41 -> -43853.28 | N37: =M41 -> -59627.47 | ... W37: =V41 -> -117489.8
A38: Payment | D38: =D6+D22 -> 0 | E38: =E6+E22 -> 0 | F38: =F6+F22 -> 0 | G38: =G6+G22-G31 -> -4000 | H38: =H6+H22-H31 -> -5652 | I38: =I6+I22+I23-I31 -> -43452 | J38: =J6+J22+J23-J31 -> -35489.44 | K38: =K6+K22+K23-K31 -> -48600 | L38: =L6+L22+L23-L31 -> -49218 | M38: =M6+M22+M23-M31 -> -50814.19 | N38: =N6+N22+N23-N31 -> -31298 | O38: =O6+O22+O23-O31 -> -51188 | P38: =P6+P22+P23-P31 -> -56402.33 | ... W38: =W6+W22+W23-W31 -> -43388
A39: Receipts | D39: =-D14-D15 -> 0 | E39: =-E14-E15 -> 0 | F39: =-F14-F15 -> 0 | G39: =-G14-G15 -> 0 | H39: =-H14-H15 -> 10000 | I39: =-I14-I15 -> 44031.2 | J39: =-J14-J15 -> 0 | K39: =-K14-K15 -> 52567.2 | ... W39: =-W14-W15 -> 101807.2
A41: C/bal | B41: =SUM(B37:B40) -> 31202.64 | C41: =SUM(C37:C40) -> 16132.54 | D41: =SUM(D37:D40) -> 4816.48 | E41: =SUM(E37:E40) -> 512.86 | F41: =SUM(F37:F40)-6000 -> 2419.76 | G41: =SUM(G37:G40) -> -1580.24 | H41: =SUM(H37:H40) -> 2767.76 | I41: =SUM(I37:I40) -> 3346.96 | J41: =SUM(J37:J40) -> -32142.48 | K41: =SUM(K37:K40) -> -28175.28 | L41: =SUM(L37:L40) -> -43853.28 | M41: =SUM(M37:M40) -> -59627.47 | N41: =SUM(N37:N40) -> -48765.47 | ... W41: =SUM(W37:W40) -> -59070.6

Sheet Balance Sheet
A1: Balance Sheet
B2: ACT | C2: Act | D2: Act | E2: Act | F2: Act | G2: Forecast | H2: Forecast | I2: Forecast | J2: Forecast | K2: Forecast | L2: Forecast | M2: Forecast | N2: Forecast | O2: Forecast | P2: Forecast | Q2: Forecast | R2: Forecast | S2: Forecast | T2: Forecast | U2: Forecast | V2: Forecast | W2: Forecast
B3: Mar-24 | C3: Apr-24 | D3: May-24 | E3: Jun-24 | F3: Jul-24 | G3: Aug-24 | H3: Sep-24 | I3: Oct-24 | J3: Nov-24 | K3: Dec-24 | L3: Jan-25 | M3: Feb-25 | N3: Mar-25 | O3: 45748 | P3: 45778 | Q3: 45809 | R3: 45839 | S3: 45870 | T3: 45901 | U3: 45931 | V3: 45962 | W3: 45992
A4: Assets
A6: Bank
A7: In Home Media | B7: =170.59+31032.05 -> 31202.64 | C7: 16132.54 | D7: 4816.48 | E7: =157.75+355.11 -> 512.86 | F7: 8419.76 | G7: ='Working Capital'!G41 -> -1580.24 | H7: ='Working Capital'!H41 -> 2767.76 | I7: ='Working Capital'!I41 -> 3346.96 | J7: ='Working Capital'!J41 -> -32142.48 | K7: ='Working Capital'!K41 -> -28175.28 | L7: ='Working Capital'!L41 -> -43853.28 | M7: ='Working Capital'!M41 -> -59627.47 | N7: ='Working Capital'!N41 -> -48765.47 | ... W7: ='Working Capital'!W41 -> -59070.6
A8: Total Bank | B8: =SUM(B7) -> 31202.64 | C8: =SUM(C7) -> 16132.54 | D8: =SUM(D7) -> 4816.48 | E8: =SUM(E7) -> 512.86 | F8: =SUM(F7) -> 8419.76 | G8: =SUM(G7) -> -1580.24 | H8: =SUM(H7) -> 2767.76 | I8: =SUM(I7) -> 3346.96 | ... W8: =SUM(W7) -> -59070.6
A10: Current Assets
A11: Accounts Receivable | B11: 63292 | C11: 85462 | D11: 107632 | E11: 129142 | F11: 21592 | G11: ='Working Capital'!G16 -> 21592 | H11: ='Working Capital'!H16 -> 50623.2 | I11: ='Working Capital'!I16 -> 6592 | J11: ='Working Capital'!J16 -> 59159.2 | K11: ='Working Capital'!K16 -> 40132 | L11: ='Working Capital'!L16 -> 41632 | M11: ='Working Capital'!M16 -> 48752 | N11: ='Working Capital'!N16 -> 50972 | ... W11: ='Working Capital'!W16 -> 58592
A12: Prepayments | B12: 8257.75 | C12: 7200.46 | D12: 6143.17 | E12: 5085.88 | F12: 5085.88 | G12: =F12 -> 5085.88 | H12: =G12 -> 5085.88 | I12: =H12 -> 5085.88 | J12: =I12 -> 5085.88 | K12: =J12 -> 5085.88 | L12: =K12 -> 5085.88 | M12: =L12 -> 5085.88 | N12: =M12 -> 5085.88 | ... W12: =V12 -> 5085.88
A13: Total Current Assets | B13: =SUM(B11:B12) -> 71549.75 | C13: =SUM(C11:C12) -> 92662.46 | D13: =SUM(D11:D12) -> 113775.17 | E13: =SUM(E11:E12) -> 134227.88 | F13: =SUM(F11:F12) -> 26677.88 | G13: =SUM(G11:G12) -> 26677.88 | H13: =SUM(H11:H12) -> 55709.08 | I13: =SUM(I11:I12) -> 11677.88 | ... W13: =SUM(W11:W12) -> 63677.88
A15: Fixed Assets
A16: Screens | B16: 0 | C16: 0 | D16: 0 | E16: 0 | F16: 0 | G16: ='Working Capital'!G34 -> 0 | H16: ='Working Capital'!H34 -> 0 | I16: ='Working Capital'!I34 -> 16900 | J16: ='Working Capital'!J34 -> 35600 | K16: ='Working Capital'!K34 -> 54300 | L16: ='Working Capital'!L34 -> 73000 | M16: ='Working Capital'!M34 -> 91700 | N16: ='Working Capital'!N34 -> 91700 | ... W16: ='Working Capital'!W34 -> 296300
A17: Less Accumulated Depreciation on Computer Equipment | B17: 0 | C17: 0 | D17: 0 | E17: 0 | F17: 0 | G17: 0 | H17: 0 | I17: 0 | J17: 0 | K17: 0 | L17: 0 | M17: 0 | N17: 0 | O17: 0 | P17: 0 | Q17: 0 | R17: 0 | S17: 0 | T17: 0 | U17: 0 | V17: 0 | W17: 0
A18: IHM MA Portal | B18: 59983.35 | C18: 60350.02 | D18: 60716.69 | E18: 69683.36 | F18: 69683.36 | G18: =F18 -> 69683.36 | H18: =G18 -> 69683.36 | I18: =H18 -> 69683.36 | J18: =I18 -> 69683.36 | K18: =J18 -> 69683.36 | L18: =K18 -> 69683.36 | M18: =L18 -> 69683.36 | N18: =M18 -> 69683.36 | ... W18: =V18 -> 69683.36
A19: Less Accumulated Depreciation on Computer Equipment | B19: 0 | C19: 0 | D19: 0 | E19: 0 | F19: 0 | G19: 0 | H19: 0 | I19: 0 | J19: 0 | K19: 0 | L19: 0 | M19: 0 | N19: 0 | O19: 0 | P19: 0 | Q19: 0 | R19: 0 | S19: 0 | T19: 0 | U19: 0 | V19: 0 | W19: 0
A20: Total Fixed Assets | B20: =SUM(B16:B19) -> 59983.35 | C20: =SUM(C16:C19) -> 60350.02 | D20: =SUM(D16:D19) -> 60716.69 | E20: =SUM(E16:E19) -> 69683.36 | F20: =SUM(F16:F19) -> 69683.36 | G20: =SUM(G16:G19) -> 69683.36 | H20: =SUM(H16:H19) -> 69683.36 | I20: =SUM(I16:I19) -> 86583.36 | ... W20: =SUM(W16:W19) -> 365983.36
A22: Total Assets | B22: =(0+(0)+(B8)+(B13)+(B20))-(0) -> 162735.74 | C22: =(0+(0)+(C8)+(C13)+(C20))-(0) -> 169145.02 | D22: =(0+(0)+(D8)+(D13)+(D20))-(0) -> 179308.34 | E22: =(0+(0)+(E8)+(E13)+(E20))-(0) -> 204424.1 | F22: =(0+(0)+(F8)+(F13)+(F20))-(0) -> 104781 | G22: =(0+(0)+(G8)+(G13)+(G20))-(0) -> 94781 | H22: =(0+(0)+(H8)+(H13)+(H20))-(0) -> 128160.2 | I22: =(0+(0)+(I8)+(I13)+(I20))-(0) -> 101608.2 | ... W22: =(0+(0)+(W8)+(W13)+(W20))-(0) -> 370590.64
A24: Liabilities
A26: Current Liabilities
A27: Accounts Payable | B27: 78309.98 | C27: 115566.38 | D27: 124836.9 | E27: 158897.03 | F27: 83451.5 | G27: ='Working Capital'!G24 -> 89103.5 | H27: ='Working Capital'!H24 -> 101503.5 | I27: ='Working Capital'!I24 -> 93603.5 | J27: ='Working Capital'!J24 -> 99881.5 | K27: ='Working Capital'!K24 -> 99499.5 | L27: ='Working Capital'!L24 -> 98589.5 | M27: ='Working Capital'!M24 -> 98279.5 | N27: ='Working Capital'!N24 -> 97369.5 | ... W27: ='Working Capital'!W24 -> 100369.5
A28: Accruals | B28: 34749.96 | C28: 34749.96 | D28: 43549.96 | E28: 54849.96 | F28: 54849.96 | G28: =F28 -> 54849.96 | H28: =G28 -> 54849.96 | I28: =H28 -> 54849.96 | J28: =I28 -> 54849.96 | K28: =J28 -> 54849.96 | L28: =K28 -> 54849.96 | M28: =L28 -> 54849.96 | N28: =M28 -> 54849.96 | ... W28: =V28 -> 54849.96
A29: PAYE Payable | B29: 7363.21 | C29: =256.83+9108.86 -> 9365.69 | D29: =513.66+11043.37 -> 11557.03 | E29: =513.66+11233.51 -> 11747.17 | F29: =513.66+11.5 -> 525.16 | G29: 0 | H29: 0 | I29: 0 | J29: 0 | K29: 0 | L29: 0 | M29: 0 | N29: 0 | O29: 0 | P29: 0 | Q29: 0 | R29: 0 | S29: 0 | T29: 0 | U29: 0 | V29: 0 | W29: 0
A30: VAT | B30: -24342.65 | C30: -27173.05 | D30: -5060.29 | E30: -5328.09 | F30: -4387.09 | G30: ='Working Capital'!G7 -> -9329.09 | H30: ='Working Capital'!H7 -> -5832.56 | I30: ='Working Capital'!I7 -> -8941.23 | J30: ='Working Capital'!J7 -> 835.86 | K30: ='Working Capital'!K7 -> 1506.19 | L30: ='Working Capital'!L7 -> 2411.52 | M30: ='Working Capital'!M7 -> 2882.33 | N30: ='Working Capital'!N7 -> 5214.33 | ... W30: ='Working Capital'!W7 -> 12457.2
A32: Total Current Liabilities | B32: =SUM(B27:B31) -> 96080.5 | C32: =SUM(C27:C31) -> 132508.98 | D32: =SUM(D27:D31) -> 174883.6 | E32: =SUM(E27:E31) -> 220166.07 | F32: =SUM(F27:F31) -> 134439.53 | G32: =SUM(G27:G31) -> 134624.37 | H32: =SUM(H27:H31) -> 150520.9 | I32: =SUM(I27:I31) -> 139512.23 | ... W32: =SUM(W27:W31) -> 167676.66
A34: Non-Current Liabilities
A39: Total Non-Current Liabilities | B39: =SUM(B35:B37) -> 0 | C39: =SUM(C35:C37) -> 0 | D39: =SUM(D35:D37) -> 0 | E39: =SUM(E35:E37) -> 0 | F39: =SUM(F35:F37) -> 0 | G39: =SUM(G35:G37) -> 0 | H39: =SUM(H35:H37) -> 0 | I39: =SUM(I35:I37) -> 0 | ... W39: =SUM(W35:W37) -> 0
A41: Total Liabilities | B41: =(0+(0)+(B32)+(B39))-(0) -> 96080.5 | C41: =(0+(0)+(C32)+(C39))-(0) -> 132508.98 | D41: =(0+(0)+(D32)+(D39))-(0) -> 174883.6 | E41: =(0+(0)+(E32)+(E39))-(0) -> 220166.07 | F41: =(0+(0)+(F32)+(F39))-(0) -> 134439.53 | G41: =(0+(0)+(G32)+(G39))-(0) -> 134624.37 | H41: =(0+(0)+(H32)+(H39))-(0) -> 150520.9 | I41: =(0+(0)+(I32)+(I39))-(0) -> 139512.23 | ... W41: =(0+(0)+(W32)+(W39))-(0) -> 167676.66
A43: Net Assets | B43: =(B22)-(B41) -> 66655.24 | C43: =(C22)-(C41) -> 36636.04 | D43: =(D22)-(D41) -> 4424.74 | E43: =(E22)-(E41) -> -15741.97 | F43: =(F22)-(F41) -> -29658.53 | G43: =(G22)-(G41) -> -39843.37 | H43: =(H22)-(H41) -> -22360.7 | I43: =(I22)-(I41) -> -37904.03 | ... W43: =(W22)-(W41) -> 202913.98
A45: Equity
A47: Current Year Earnings | B47: -68501.83 | C47: -98179.85 | D47: -130391.15 | E47: -150873.36 | F47: -164474.42 | G47: =F47+'Consolidated P&L'!G57 -> -169184.42 | H47: =G47+'Consolidated P&L'!H57 -> -151701.75 | I47: =H47+'Consolidated P&L'!I57 -> -167245.08 | J47: =I47+'Consolidated P&L'!J57 -> -147522.41 | K47: =J47+'Consolidated P&L'!K57 -> -144170.74 | L47: =K47+'Consolidated P&L'!L57 -> -139644.07 | M47: =L47+'Consolidated P&L'!M57 -> -129759.07 | N47: =M47+'Consolidated P&L'!N57 -> -118099.06 | ... W47: =V47+'Consolidated P&L'!W57 -> 73572.967
A48: Retained Earnings | B48: -115184.11 | C48: -115184.11 | D48: -115184.11 | E48: -115184.11 | F48: -115184.11 | G48: =F48 -> -115184.11 | H48: =G48 -> -115184.11 | I48: =H48 -> -115184.11 | J48: =I48 -> -115184.11 | K48: =J48 -> -115184.11 | L48: =K48 -> -115184.11 | M48: =L48 -> -115184.11 | N48: =M48 -> -115184.11 | ... W48: =V48 -> -115184.11
A49: Share Premium | B49: 250000 | C49: 250000 | D49: 250000 | E49: 250000 | F49: 250000 | G49: =F49 -> 250000 | H49: =G49 -> 250000 | I49: =H49 -> 250000 | J49: =I49 -> 250000 | K49: =J49 -> 250000 | L49: =K49 -> 250000 | M49: =L49 -> 250000 | N49: =M49 -> 250000 | ... W49: =V49 -> 250000
A51: Total Equity | B51: =SUM(B46:B50) -> 66314.06 | C51: =SUM(C46:C50) -> 36636.04 | D51: =SUM(D46:D50) -> 4424.74 | E51: =SUM(E46:E50) -> -16057.47 | F51: =SUM(F46:F50) -> -29658.53 | G51: =SUM(G46:G50) -> -34368.53 | H51: =SUM(H46:H50) -> -16885.86 | I51: =SUM(I46:I50) -> -32429.19 | ... W51: =SUM(W46:W50) -> 208388.86
B52: =B43-B51 -> 341.18 | C52: =C43-C51 -> 0 | D52: =D43-D51 -> 2.910383e-11 | E52: =E43-E51 -> 315.5 | F52: =F43-F51 -> 2.910383e-11 | G52: =G43-G51 -> -5474.84 | H52: =H43-H51 -> -5474.84 | I52: =I43-I51 -> -5474.84 | ... W52: =W43-W51 -> -5474.8767

Sheet Cashflow
A1: Cashflow | B1: 2024/2025
B3: 45352 | C3: 45383 | D3: 45413 | E3: 45444 | F3: 45474 | G3: 45505 | H3: 45536 | I3: 45566 | J3: 45597 | K3: 45627 | L3: 45658 | M3: 45689 | N3: 45717 | O3: 45748 | P3: 45778 | Q3: 45809 | R3: 45839 | S3: 45870 | T3: 45901 | U3: 45931 | V3: 45962 | W3: 45992
A6: Net Profit (Excl' Depreciation) | B6: ='Consolidated P&L'!B50-'Consolidated P&L'!B54 -> -33570.76 | C6: ='Consolidated P&L'!C50-'Consolidated P&L'!C54 -> -26981.97 | D6: ='Consolidated P&L'!D50-'Consolidated P&L'!D54 -> -32061.3 | E6: ='Consolidated P&L'!E50-'Consolidated P&L'!E54 -> -20291.72 | F6: ='Consolidated P&L'!F50-'Consolidated P&L'!F54 -> -13601.06 | G6: ='Consolidated P&L'!G50-'Consolidated P&L'!G54 -> -4710 | H6: ='Consolidated P&L'!H50-'Consolidated P&L'!H54 -> 17482.67 | I6: ='Consolidated P&L'!I50-'Consolidated P&L'!I54 -> -15543.33 | ... W6: ='Consolidated P&L'!W50-'Consolidated P&L'!W54 -> 8010.0033
A8: Change in Current Assets
A9: Change in Trade Debtors | B9: =-'Balance Sheet'!B11 -> -63292 | C9: =-'Balance Sheet'!C11+'Balance Sheet'!B11 -> -22170 | D9: =-'Balance Sheet'!D11+'Balance Sheet'!C11 -> -22170 | E9: =-'Balance Sheet'!E11+'Balance Sheet'!D11 -> -21510 | F9: =-'Balance Sheet'!F11+'Balance Sheet'!E11 -> 107550 | G9: =-'Balance Sheet'!G11+'Balance Sheet'!F11 -> 0 | H9: =-'Balance Sheet'!H11+'Balance Sheet'!G11 -> -29031.2 | I9: =-'Balance Sheet'!I11+'Balance Sheet'!H11 -> 44031.2 | J9: =-'Balance Sheet'!J11+'Balance Sheet'!I11 -> -52567.2 | ... W9: =-'Balance Sheet'!W11+'Balance Sheet'!V11 -> 49807.2
A10: Change in Prepayments | B10: 0 | C10: =-'Balance Sheet'!C12+'Balance Sheet'!B12 -> 1057.29 | D10: =-'Balance Sheet'!D12+'Balance Sheet'!C12 -> 1057.29 | E10: =-'Balance Sheet'!E12+'Balance Sheet'!D12 -> 1057.29 | F10: =-'Balance Sheet'!F12+'Balance Sheet'!E12 -> 0 | G10: =-'Balance Sheet'!G12+'Balance Sheet'!F12 -> 0 | H10: =-'Balance Sheet'!H12+'Balance Sheet'!G12 -> 0 | I10: =-'Balance Sheet'!I12+'Balance Sheet'!H12 -> 0 | J10: =-'Balance Sheet'!J12+'Balance Sheet'!I12 -> 0 | ... W10: =-'Balance Sheet'!W12+'Balance Sheet'!V12 -> 0
A12: Change in Current Liabilities
A14: Change in Trade Creditors | B14: ='Balance Sheet'!B27 -> 78309.98 | C14: ='Balance Sheet'!C27-'Balance Sheet'!B27 -> 37256.4 | D14: ='Balance Sheet'!D27-'Balance Sheet'!C27 -> 9270.52 | E14: ='Balance Sheet'!E27-'Balance Sheet'!D27 -> 34060.13 | F14: ='Balance Sheet'!F27-'Balance Sheet'!E27 -> -75445.53 | G14: ='Balance Sheet'!G27-'Balance Sheet'!F27 -> 5652 | H14: ='Balance Sheet'!H27-'Balance Sheet'!G27 -> 12400 | I14: ='Balance Sheet'!I27-'Balance Sheet'!H27 -> -7900 | J14: ='Balance Sheet'!J27-'Balance Sheet'!I27 -> 6278 | ... W14: ='Balance Sheet'!W27-'Balance Sheet'!V27 -> -1000
A15: Change in VAT | B15: ='Balance Sheet'!B30 -> -24342.65 | C15: ='Balance Sheet'!C30-'Balance Sheet'!B30 -> -2830.4 | D15: ='Balance Sheet'!D30-'Balance Sheet'!C30 -> 22112.76 | E15: ='Balance Sheet'!E30-'Balance Sheet'!D30 -> -267.8 | F15: ='Balance Sheet'!F30-'Balance Sheet'!E30 -> 941 | G15: ='Balance Sheet'!G30-'Balance Sheet'!F30 -> -4942 | H15: ='Balance Sheet'!H30-'Balance Sheet'!G30 -> 3496.53 | I15: ='Balance Sheet'!I30-'Balance Sheet'!H30 -> -3108.67 | J15: ='Balance Sheet'!J30-'Balance Sheet'!I30 -> 9777.09 | ... W15: ='Balance Sheet'!W30-'Balance Sheet'!V30 -> 1602
A16: Change in Accruals | B16: 0 | C16: ='Balance Sheet'!C28-'Balance Sheet'!B28 -> 0 | D16: ='Balance Sheet'!D28-'Balance Sheet'!C28 -> 8800 | E16: ='Balance Sheet'!E28-'Balance Sheet'!D28 -> 11300 | F16: ='Balance Sheet'!F28-'Balance Sheet'!E28 -> 0 | G16: ='Balance Sheet'!G28-'Balance Sheet'!F28 -> 0 | H16: ='Balance Sheet'!H28-'Balance Sheet'!G28 -> 0 | I16: ='Balance Sheet'!I28-'Balance Sheet'!H28 -> 0 | J16: ='Balance Sheet'!J28-'Balance Sheet'!I28 -> 0 | ... W16: ='Balance Sheet'!W28-'Balance Sheet'!V28 -> 0
A17: Change in Corporation Tax
A19: Add back depreciation | B19: ='Consolidated P&L'!B54 -> 0 | C19: ='Consolidated P&L'!C54 -> 0 | D19: ='Consolidated P&L'!D54 -> 0 | E19: ='Consolidated P&L'!E54 -> 0 | F19: ='Consolidated P&L'!F54 -> 0 | G19: ='Consolidated P&L'!G54 -> 0 | H19: ='Consolidated P&L'!H54 -> 0 | I19: ='Consolidated P&L'!I54 -> 0 | ... W19: ='Consolidated P&L'!W54 -> 0
A21: NET CASH FLOW FROM OPERATIONS | B21: =SUM(B6:B20) -> -42895.43 | C21: =SUM(C6:C20) -> -13668.68 | D21: =SUM(D6:D20) -> -12990.73 | E21: =SUM(E6:E20) -> 4347.9 | F21: =SUM(F6:F20) -> 19444.41 | G21: =SUM(G6:G20) -> -4000 | H21: =SUM(H6:H20) -> 4348 | I21: =SUM(I6:I20) -> 17479.2 | ... W21: =SUM(W6:W20) -> 58419.203
A23: Capital Expenditure | G23: =-'Balance Sheet'!G18+'Balance Sheet'!F18-'Balance Sheet'!G16+'Balance Sheet'!F16 -> 0 | H23: =-'Balance Sheet'!H18+'Balance Sheet'!G18-'Balance Sheet'!H16+'Balance Sheet'!G16 -> 0 | I23: =-'Balance Sheet'!I18+'Balance Sheet'!H18-'Balance Sheet'!I16+'Balance Sheet'!H16 -> -16900 | J23: =-'Balance Sheet'!J18+'Balance Sheet'!I18-'Balance Sheet'!J16+'Balance Sheet'!I16 -> -18700 | K23: =-'Balance Sheet'!K18+'Balance Sheet'!J18-'Balance Sheet'!K16+'Balance Sheet'!J16 -> -18700 | L23: =-'Balance Sheet'!L18+'Balance Sheet'!K18-'Balance Sheet'!L16+'Balance Sheet'!K16 -> -18700 | M23: =-'Balance Sheet'!M18+'Balance Sheet'!L18-'Balance Sheet'!M16+'Balance Sheet'!L16 -> -18700 | N23: =-'Balance Sheet'!N18+'Balance Sheet'!M18-'Balance Sheet'!N16+'Balance Sheet'!M16 -> 0 | ... W23: =-'Balance Sheet'!W18+'Balance Sheet'!V18-'Balance Sheet'!W16+'Balance Sheet'!V16 -> 0
A24: Loans | B24: =-'Consolidated P&L'!B53 -> 0 | C24: =-'Consolidated P&L'!C53 -> 0 | D24: =-'Consolidated P&L'!D53 -> 0 | E24: =-'Consolidated P&L'!E53 -> 0 | F24: =-'Consolidated P&L'!F53 -> 0 | G24: =-'Consolidated P&L'!G53 -> 0 | H24: =-'Consolidated P&L'!H53 -> 0 | I24: =-'Consolidated P&L'!I53 -> 0 | ... W24: =-'Consolidated P&L'!W53 -> 0
A26: NET CASH FLOW FROM FINANCING & INVESTMENTS | B26: =SUM(B21:B25) -> -42895.43 | C26: =SUM(C21:C25) -> -13668.68 | D26: =SUM(D21:D25) -> -12990.73 | E26: =SUM(E21:E25) -> 4347.9 | F26: =SUM(F21:F25) -> 19444.41 | G26: =SUM(G21:G25) -> -4000 | H26: =SUM(H21:H25) -> 4348 | I26: =SUM(I21:I25) -> 579.2 | ... W26: =SUM(W21:W25) -> 58419.203
A28: Dividends | B28: 0 | C28: 0 | D28: 0 | E28: 0 | F28: 0 | G28: 0 | H28: 0 | I28: 0 | J28: 0 | K28: 0 | L28: 0 | M28: 0 | N28: 0 | O28: 0 | P28: 0 | Q28: 0 | R28: 0 | S28: 0 | T28: 0 | U28: 0 | V28: 0 | W28: 0
A30: Increase / decrease in cash | B30: =SUM(B26:B29) -> -42895.43 | C30: =SUM(C26:C29) -> -13668.68 | D30: =SUM(D26:D29) -> -12990.73 | E30: =SUM(E26:E29) -> 4347.9 | F30: =SUM(F26:F29) -> 19444.41 | G30: =SUM(G26:G29) -> -4000 | H30: =SUM(H26:H29) -> 4348 | I30: =SUM(I26:I29) -> 579.2 | ... W30: =SUM(W26:W29) -> 58419.203
A32: Cash b/f | B32: 0 | C32: =B34 -> 31202.57 | D32: =C34 -> 16132.89 | E32: =D34 -> 4816.16 | F32: =E34 -> 513.06 | G32: =F34 -> 2419.47 | H32: =G34 -> -1580.53 | I32: =H34 -> 2767.47 | J32: =I34 -> 3346.67 | ... W32: =V34 -> -117490.06
A34: Cash c/f | B34: =B30+B32+74098 -> 31202.57 | C34: =C30+C32-1401 -> 16132.89 | D34: =D30+D32+1674 -> 4816.16 | E34: =E30+E32-8651 -> 513.06 | F34: =F30+F32-17538 -> 2419.47 | G34: =G30+G32 -> -1580.53 | H34: =H30+H32 -> 2767.47 | I34: =I30+I32 -> 3346.67 | J34: =J30+J32 -> -32142.77 | K34: =K30+K32 -> -28175.57 | L34: =L30+L32 -> -43853.57 | M34: =M30+M32 -> -59627.757 | N34: =N30+N32 -> -48765.753 | ... W34: =W30+W32 -> -59070.853
B35: ='Working Capital'!B41 -> 31202.64 | C35: ='Working Capital'!C41 -> 16132.54 | D35: ='Working Capital'!D41 -> 4816.48 | E35: ='Working Capital'!E41 -> 512.86 | F35: ='Working Capital'!F41 -> 2419.76 | G35: ='Working Capital'!G41 -> -1580.24 | H35: ='Working Capital'!H41 -> 2767.76 | I35: ='Working Capital'!I41 -> 3346.96 | ... W35: ='Working Capital'!W41 -> -59070.6
B36: =B34-B35 -> -0.07 | C36: =C34-C35 -> 0.35 | D36: =D34-D35 -> -0.32 | E36: =E34-E35 -> 0.2 | F36: =F34-F35 -> -0.29 | G36: =G34-G35 -> -0.29 | H36: =H34-H35 -> -0.29 | I36: =I34-I35 -> -0.29 | ... W36: =W34-W35 -> -0.25333333
C37: =C36+B36 -> 0.28

Sheet Aged receivables 
A1: Aged Receivables Summary
A2: IN HOME MEDIA LTD
A3: As at 13 August 2024
A5: Contact | B5: < 1 Month | C5: 1 Month | D5: 2 Months | E5: 3 Months | F5: Older | G5: Total
A6: Budenberg / Xenia Estates | B6: 0 | C6: 540 | D6: 1080 | E6: 540 | F6: 19192 | G6: 21352
A7: Walk In Media | B7: 0 | C7: 120 | D7: 120 | E7: 0 | F7: 0 | G7: 240
A8: Total | B8: =SUM(B6:B7) -> 0 | C8: =SUM(C6:C7) -> 660 | D8: =SUM(D6:D7) -> 1200 | E8: =SUM(E6:E7) -> 540 | F8: =SUM(F6:F7) -> 19192 | G8: =SUM(G6:G7) -> 21592
A10: Percentage of total | B10: =(B8 / SUM(B8:F8)) -> 0 | C10: =(C8 / SUM(B8:F8)) -> 0.030566877 | D10: =(D8 / SUM(B8:F8)) -> 0.055576139 | E10: =(E8 / SUM(B8:F8)) -> 0.025009263 | F10: =(F8 / SUM(B8:F8)) -> 0.88884772 | G10: =(G8 / G8) -> 1

Sheet Aged payable
A1: Aged Payables Summary
A2: IN HOME MEDIA LTD
A3: As at 13 August 2024
A5: Contact | B5: < 1 Month | C5: 1 Month | D5: 2 Months | E5: 3 Months | F5: Older | G5: Total
A7: Aged Payables
A8: Ameco | B8: 0 | C8: 2191.66 | D8: 175.52 | E8: 0 | F8: 13396.38 | G8: =SUM(B8:F8) -> 15763.56
A9: Eris Connect Limited | B9: 0 | C9: 7200 | D9: 0 | E9: 7200 | F9: 14400
A10: LDSK | B10: 3088.8 | C10: 3220.8 | D10: 3300 | E10: 6890.4 | F10: 8289.6 | G10: =SUM(B10:F10) -> 24789.6
A11: Steele Raymond | B11: 0 | C11: 2970 | D11: 0 | E11: 0 | F11: 0 | G11: =SUM(B11:F11) -> 2970
A12: Total Aged Payables | B12: =SUM(B8:B11) -> 3088.8 | C12: =SUM(C8:C11) -> 15582.46 | D12: =SUM(D8:D11) -> 3475.52 | E12: =SUM(E8:E11) -> 14090.4 | F12: =SUM(F8:F11) -> 36085.98 | G12: =SUM(G8:G11) -> 43523.16
A14: Total | B14: =B12 -> 3088.8 | C14: =C12 -> 15582.46 | D14: =D12 -> 3475.52 | E14: =E12 -> 14090.4 | F14: =F12 -> 36085.98 | G14: =G12 -> 43523.16
A16: Percentage of total | B16: =(B12 / SUM(B12:F12)) -> 0.042708311 | C16: =(C12 / SUM(B12:F12)) -> 0.21545602 | D16: =(D12 / SUM(B12:F12)) -> 0.048055422 | E16: =(E12 / SUM(B12:F12)) -> 0.19482556 | F16: =(F12 / SUM(B12:F12)) -> 0.49895469 | G16: =(G12 / G12) -> 1

Sheet 4th P&L
C1: 2023/2024
A2: 4th P&L | B2: Per Screen | C2: 44986 | D2: 45017 | E2: 45047 | F2: 45078 | G2: 45108 | H2: 45139 | I2: 45170 | J2: 45200 | K2: 45231 | L2: 45261 | M2: 45292 | N2: 45323 | O2: 45352 | Q2: YE Feb-24 | AA2: Apr-24 | AB2: May-24 | AC2: Jun-24 | AD2: Jul-24 | AE2: Aug-24 | AF2: Sep-24 | AG2: Oct-24 | AH2: Nov-24 | AI2: Dec-24 | AJ2: Jan-25 | AK2: Feb-25 | AL2: Mar-25 | AM2: Apr-25 | AN2: May-25 | AO2: Jun-25 | AP2: Jul-25 | AQ2: Aug-25 | AR2: Sep-25 | AS2: Oct-25 | AT2: Nov-25 | AU2: Dec-25 | AV2: Jan-26 | AW2: Feb-26 | AX2: Mar-26 | BC2: =#REF! -> #REF!
C3: Actual | D3: Actual | E3: Actual | F3: Actual | G3: Actual | H3: FORECAST | I3: FORECAST | J3: FORECAST | K3: FORECAST | L3: FORECAST | M3: FORECAST | N3: FORECAST | O3: FORECAST | BC3: =#REF!&BC2 -> #REF!
A4: Income
A5: New screens | C5: 30 | D5: 30 | E5: 0 | F5: 30 | G5: 30 | H5: 50 | I5: 50 | J5: 50 | K5: 50 | L5: 50 | M5: 50 | N5: 50 | O5: 30
A6: Live screens | C6: 120 | D6: =C6+30 -> 150 | E6: =D6 -> 150 | F6: =E6+30 -> 180 | G6: =F6+G5 -> 210 | H6: =G6+H5 -> 260 | I6: =H6+I5 -> 310 | J6: =I6+J5 -> 360 | K6: =J6+K5 -> 410 | L6: =K6+L5 -> 460 | M6: =L6+M5 -> 510 | N6: =M6+N5 -> 560 | O6: =N6+O5 -> 590
A7: Revenue - new screens | B7: 1000 | C7: ='Sales forecast'!C6 -> 30000 | D7: ='Sales forecast'!D6 -> 30000 | E7: 0 | F7: 30000 | G7: 30000 | H7: =$B7*H$5 -> 50000 | I7: =$B7*I$5 -> 50000 | J7: =$B7*J$5 -> 50000 | K7: =$B7*K$5 -> 50000 | L7: =$B7*L$5 -> 50000 | M7: =$B7*M$5 -> 50000 | N7: =$B7*N$5 -> 50000 | O7: =$B7*O$5 -> 30000 | Q7: =SUM(C7:N7) -> 470000 | AA7: #REF! | AB7: #REF! | AC7: #REF! | AD7: #REF! | AE7: #REF! | AF7: #REF! | AG7: #REF! | AH7: #REF! | AI7: #REF! | AJ7: #REF! | AK7: #REF! | AL7: #REF! | AM7: #REF! | AN7: #REF! | AO7: #REF! | AP7: #REF! | AQ7: #REF! | AR7: #REF! | AS7: #REF! | AT7: #REF! | AU7: #REF! | AV7: #REF! | AW7: #REF! | AX7: #REF! | BB7: =SUM(D7:O7) -> 470000 | BC7: =SUM(OFFSET(#REF!,0,0,1,MATCH(#REF!,#REF!,0))) -> #REF! | BD7: =SUM(#REF!) -> #REF! | BE7: =SUM(C7) -> 30000
A8: Revenue - set up and instalation | B8: 750 | C8: 0 | D8: ='Sales forecast'!D7 -> 7800 | E8: 5620 | F8: =10902+6521 -> 17423 | G8: =10675.8+780+540+264+264 -> 12523.8 | H8: =$B8*H$5 -> 37500 | I8: =$B8*I$5 -> 37500 | J8: =$B8*J$5 -> 37500 | K8: =$B8*K$5 -> 37500 | L8: =$B8*L$5 -> 37500 | M8: =$B8*M$5 -> 37500 | N8: =$B8*N$5 -> 37500 | O8: =$B8*O$5 -> 22500 | Q8: =SUM(C8:N8) -> 305866.8 | AA8: #REF! | AB8: #REF! | AC8: #REF! | AD8: #REF! | AE8: #REF! | AF8: #REF! | AG8: #REF! | AH8: #REF! | AI8: #REF! | AJ8: #REF! | AK8: #REF! | AL8: #REF! | AM8: #REF! | AN8: #REF! | AO8: #REF! | AP8: #REF! | AQ8: #REF! | AR8: #REF! | AS8: #REF! | AT8: #REF! | AU8: #REF! | AV8: #REF! | AW8: #REF! | AX8: #REF! | BB8: =SUM(D8:O8) -> 328366.8 | BC8: =SUM(OFFSET(#REF!,0,0,1,MATCH(#REF!,#REF!,0))) -> #REF! | BD8: =SUM(#REF!) -> #REF! | BE8: =SUM(C8) -> 0
A9: Revenue - Survey | B9: 250 | H9: =$B$9*H5 -> 12500 | I9: =$B$9*I5 -> 12500 | J9: =$B$9*J5 -> 12500 | K9: =$B$9*K5 -> 12500 | L9: =$B$9*L5 -> 12500 | M9: =$B$9*M5 -> 12500 | N9: =$B$9*N5 -> 12500
